<sdf version='1.7'>
  <world name='default'>
    <physics type='ode'>
      <ode>
        <solver>
          <type>quick</type>
          <iters>20</iters>
          <sor>1</sor>
          <use_dynamic_moi_rescaling>0</use_dynamic_moi_rescaling>
        </solver>
        <constraints>
          <cfm>0</cfm>
          <erp>0.2</erp>
          <contact_max_correcting_vel>100</contact_max_correcting_vel>
          <contact_surface_layer>0</contact_surface_layer>
        </constraints>
      </ode>
      <real_time_update_rate>1000</real_time_update_rate>
      <max_step_size>0.001</max_step_size>
      <real_time_factor>1</real_time_factor>
    </physics>
    <light name='sun' type='directional'>
      <cast_shadows>1</cast_shadows>
      <pose>0 0 10 0 -0 0</pose>
      <diffuse>0.8 0.8 0.8 1</diffuse>
      <specular>0.2 0.2 0.2 1</specular>
      <attenuation>
        <range>1000</range>
        <constant>0.9</constant>
        <linear>0.01</linear>
        <quadratic>0.001</quadratic>
      </attenuation>
      <direction>-0.5 0.1 -0.9</direction>
      <spot>
        <inner_angle>0</inner_angle>
        <outer_angle>0</outer_angle>
        <falloff>0</falloff>
      </spot>
    </light>
    <model name='ground_plane'>
      <static>1</static>
      <link name='link'>
        <collision name='collision'>
          <geometry>
            <plane>
              <normal>0 0 1</normal>
              <size>100 100</size>
            </plane>
          </geometry>
          <surface>
            <contact>
              <collide_bitmask>65535</collide_bitmask>
              <ode/>
            </contact>
            <friction>
              <ode>
                <mu>100</mu>
                <mu2>50</mu2>
              </ode>
              <torsional>
                <ode/>
              </torsional>
            </friction>
            <bounce/>
          </surface>
          <max_contacts>10</max_contacts>
        </collision>
        <visual name='visual'>
          <cast_shadows>0</cast_shadows>
          <geometry>
            <plane>
              <normal>0 0 1</normal>
              <size>100 100</size>
            </plane>
          </geometry>
          <material>
            <script>
              <uri>file://media/materials/scripts/gazebo.material</uri>
              <name>Gazebo/Grey</name>
            </script>
          </material>
        </visual>
        <self_collide>0</self_collide>
        <enable_wind>0</enable_wind>
        <kinematic>0</kinematic>
      </link>
    </model>
    <gravity>0 0 -9.81</gravity>
    <magnetic_field>6e-06 2.3e-05 -4.2e-05</magnetic_field>
    <atmosphere type='adiabatic'/>
    <scene>
      <ambient>0.4 0.4 0.4 1</ambient>
      <background>0.7 0.7 0.7 1</background>
      <shadows>1</shadows>
    </scene>
    <wind/>
    <spherical_coordinates>
      <surface_model>EARTH_WGS84</surface_model>
      <latitude_deg>0</latitude_deg>
      <longitude_deg>0</longitude_deg>
      <elevation>0</elevation>
      <heading_deg>0</heading_deg>
    </spherical_coordinates>
    <model name='tiago'>
      <link name='base_footprint'>
        <inertial>
          <pose>-0.00978 -0.00152 0.213783 0 -0 0</pose>
          <mass>42.8506</mass>
          <inertia>
            <ixx>2.01958</ixx>
            <ixy>0.00074088</ixy>
            <ixz>0.109957</ixz>
            <iyy>2.0976</iyy>
            <iyz>0.0139293</iyz>
            <izz>0.666852</izz>
          </inertia>
        </inertial>
        <collision name='base_footprint_fixed_joint_lump__base_link_collision'>
          <pose>0 0 0.0985 0 -0 0</pose>
          <geometry>
            <mesh>
              <scale>1 1 1</scale>
              <uri>/home/adriano/Desktop/tiago_public_ws/src/pmb2_robot/pmb2_description/meshes/base/base_collision.stl</uri>
            </mesh>
          </geometry>
          <surface>
            <contact>
              <ode/>
            </contact>
            <friction>
              <ode/>
              <torsional>
                <ode/>
              </torsional>
            </friction>
            <bounce/>
          </surface>
          <max_contacts>10</max_contacts>
        </collision>
        <collision name='base_footprint_fixed_joint_lump__base_antenna_left_link_collision_1'>
          <pose>-0.201 0.1062 0.3785 0 -0 0</pose>
          <geometry>
            <cylinder>
              <length>0.17</length>
              <radius>0.005</radius>
            </cylinder>
          </geometry>
          <surface>
            <contact>
              <ode/>
            </contact>
            <friction>
              <ode/>
              <torsional>
                <ode/>
              </torsional>
            </friction>
            <bounce/>
          </surface>
          <max_contacts>10</max_contacts>
        </collision>
        <collision name='base_footprint_fixed_joint_lump__base_antenna_right_link_collision_2'>
          <pose>-0.201 -0.1062 0.3785 0 -0 0</pose>
          <geometry>
            <cylinder>
              <length>0.17</length>
              <radius>0.005</radius>
            </cylinder>
          </geometry>
          <surface>
            <contact>
              <ode/>
            </contact>
            <friction>
              <ode/>
              <torsional>
                <ode/>
              </torsional>
            </friction>
            <bounce/>
          </surface>
          <max_contacts>10</max_contacts>
        </collision>
        <collision name='base_footprint_fixed_joint_lump__torso_fixed_column_link_collision_3'>
          <pose>-0.062 0 0.5685 0 -0 0</pose>
          <geometry>
            <box>
              <size>0.23 0.253 0.45</size>
            </box>
          </geometry>
          <surface>
            <contact>
              <ode/>
            </contact>
            <friction>
              <ode/>
              <torsional>
                <ode/>
              </torsional>
            </friction>
            <bounce/>
          </surface>
          <max_contacts>10</max_contacts>
        </collision>
        <collision name='base_footprint_fixed_joint_lump__torso_fixed_link_collision_4'>
          <pose>0.023 0 0.3115 0 -0 0</pose>
          <geometry>
            <box>
              <size>0.4 0.265 0.05</size>
            </box>
          </geometry>
          <max_contacts>10</max_contacts>
          <surface>
            <contact>
              <ode/>
            </contact>
            <bounce/>
            <friction>
              <torsional>
                <ode/>
              </torsional>
              <ode/>
            </friction>
          </surface>
        </collision>
        <collision name='base_footprint_fixed_joint_lump__torso_fixed_link_collision_5'>
          <pose>-0.062 0 0.3415 0 -0 0</pose>
          <geometry>
            <box>
              <size>0.255 0.255 0.117</size>
            </box>
          </geometry>
          <max_contacts>10</max_contacts>
          <surface>
            <contact>
              <ode/>
            </contact>
            <bounce/>
            <friction>
              <torsional>
                <ode/>
              </torsional>
              <ode/>
            </friction>
          </surface>
        </collision>
        <visual name='base_footprint_fixed_joint_lump__base_link_visual'>
          <pose>0 0 0.0985 0 -0 0</pose>
          <geometry>
            <mesh>
              <scale>1 1 1</scale>
              <uri>/home/adriano/Desktop/tiago_public_ws/src/pmb2_robot/pmb2_description/meshes/base/base.stl</uri>
            </mesh>
          </geometry>
          <material>
            <script>
              <name>Gazebo/White</name>
              <uri>file://media/materials/scripts/gazebo.material</uri>
            </script>
          </material>
        </visual>
        <visual name='base_footprint_fixed_joint_lump__base_antenna_left_link_visual_1'>
          <pose>-0.201 0.1062 0.2935 0 -0 0</pose>
          <geometry>
            <mesh>
              <scale>1 1 1</scale>
              <uri>/home/adriano/Desktop/tiago_public_ws/src/pmb2_robot/pmb2_description/meshes/objects/antenna.stl</uri>
            </mesh>
          </geometry>
          <material>
            <script>
              <name>Gazebo/Black</name>
              <uri>file://media/materials/scripts/gazebo.material</uri>
            </script>
          </material>
        </visual>
        <visual name='base_footprint_fixed_joint_lump__base_antenna_right_link_visual_2'>
          <pose>-0.201 -0.1062 0.2935 0 -0 0</pose>
          <geometry>
            <mesh>
              <scale>1 1 1</scale>
              <uri>/home/adriano/Desktop/tiago_public_ws/src/pmb2_robot/pmb2_description/meshes/objects/antenna.stl</uri>
            </mesh>
          </geometry>
          <material>
            <script>
              <name>Gazebo/Black</name>
              <uri>file://media/materials/scripts/gazebo.material</uri>
            </script>
          </material>
        </visual>
        <visual name='base_footprint_fixed_joint_lump__base_laser_link_visual_3'>
          <pose>0.202 0 0.0945 0 -0 0</pose>
          <geometry>
            <mesh>
              <scale>1 1 1</scale>
              <uri>/home/adriano/Desktop/tiago_public_ws/src/pmb2_robot/pmb2_description/meshes/sensors/sick_tim551.stl</uri>
            </mesh>
          </geometry>
          <material>
            <script>
              <name>Gazebo/DarkGrey</name>
              <uri>file://media/materials/scripts/gazebo.material</uri>
            </script>
          </material>
        </visual>
        <visual name='base_footprint_fixed_joint_lump__base_sonar_01_link_visual_4'>
          <pose>-0.183 -0.183 0.2715 0 0 -2.35619</pose>
          <geometry>
            <mesh>
              <scale>1 1 1</scale>
              <uri>/home/adriano/Desktop/tiago_public_ws/src/pmb2_robot/pmb2_description/meshes/sensors/srf05.stl</uri>
            </mesh>
          </geometry>
          <material>
            <script>
              <name>Gazebo/DarkGrey</name>
              <uri>file://media/materials/scripts/gazebo.material</uri>
            </script>
          </material>
        </visual>
        <visual name='base_footprint_fixed_joint_lump__base_sonar_02_link_visual_5'>
          <pose>-0.259 0 0.2715 0 -0 3.14159</pose>
          <geometry>
            <mesh>
              <scale>1 1 1</scale>
              <uri>/home/adriano/Desktop/tiago_public_ws/src/pmb2_robot/pmb2_description/meshes/sensors/srf05.stl</uri>
            </mesh>
          </geometry>
          <material>
            <script>
              <name>Gazebo/DarkGrey</name>
              <uri>file://media/materials/scripts/gazebo.material</uri>
            </script>
          </material>
        </visual>
        <visual name='base_footprint_fixed_joint_lump__base_sonar_03_link_visual_6'>
          <pose>-0.183 0.183 0.2715 0 -0 2.35619</pose>
          <geometry>
            <mesh>
              <scale>1 1 1</scale>
              <uri>/home/adriano/Desktop/tiago_public_ws/src/pmb2_robot/pmb2_description/meshes/sensors/srf05.stl</uri>
            </mesh>
          </geometry>
          <material>
            <script>
              <name>Gazebo/DarkGrey</name>
              <uri>file://media/materials/scripts/gazebo.material</uri>
            </script>
          </material>
        </visual>
        <visual name='base_footprint_fixed_joint_lump__torso_fixed_column_link_visual_7'>
          <pose>-0.062 0 0.5685 0 -0 0</pose>
          <geometry>
            <box>
              <size>0.18 0.2 0.55</size>
            </box>
          </geometry>
          <material>
            <script>
              <name>Gazebo/DarkGrey</name>
              <uri>file://media/materials/scripts/gazebo.material</uri>
            </script>
          </material>
        </visual>
        <visual name='base_footprint_fixed_joint_lump__torso_fixed_link_visual_8'>
          <pose>-0.062 0 0.2915 0 -0 0</pose>
          <geometry>
            <mesh>
              <scale>1 1 1</scale>
              <uri>/home/adriano/Desktop/tiago_public_ws/src/tiago_robot/tiago_description/meshes/torso/torso_fix.stl</uri>
            </mesh>
          </geometry>
        </visual>
        <visual name='base_footprint_fixed_joint_lump__base_cover_link_visual_9'>
          <pose>0 0 0.13 0 -0 0</pose>
          <geometry>
            <mesh>
              <scale>1 1 1</scale>
              <uri>/home/adriano/Desktop/tiago_public_ws/src/pmb2_robot/pmb2_description/meshes/base/base_ring.stl</uri>
            </mesh>
          </geometry>
          <material>
            <script>
              <name>Gazebo/Orange</name>
              <uri>file://media/materials/scripts/gazebo.material</uri>
            </script>
          </material>
        </visual>
        <sensor name='imu_sensor' type='imu'>
          <always_on>1</always_on>
          <update_rate>1000</update_rate>
          <imu>
            <noise>
              <type>gaussian</type>
              <rate>
                <mean>0.0</mean>
                <stddev>2e-4</stddev>
                <bias_mean>0.0000075</bias_mean>
                <bias_stddev>0.0000008</bias_stddev>
              </rate>
              <accel>
                <mean>0.0</mean>
                <stddev>1.7e-2</stddev>
                <bias_mean>0.1</bias_mean>
                <bias_stddev>0.001</bias_stddev>
              </accel>
            </noise>
          </imu>
          <pose>0.10171 0 0.21132 0 0 -1.5708</pose>
        </sensor>
        <sensor name='base_imu_sensor' type='imu'>
          <always_on>1</always_on>
          <update_rate>100</update_rate>
          <imu>
            <noise>
              <type>gaussian</type>
              <rate>
                <mean>0.0</mean>
                <stddev>2e-4</stddev>
                <bias_mean>0.0000075</bias_mean>
                <bias_stddev>0.0000008</bias_stddev>
              </rate>
              <accel>
                <mean>0.0</mean>
                <stddev>1.7e-2</stddev>
                <bias_mean>0.1</bias_mean>
                <bias_stddev>0.001</bias_stddev>
              </accel>
            </noise>
          </imu>
          <pose>0.10171 0 0.21132 0 0 -1.5708</pose>
        </sensor>
        <sensor name='base_laser' type='gpu_ray'>
          <update_rate>10</update_rate>
          <visualize>1</visualize>
          <ray>
            <scan>
              <horizontal>
                <samples>666</samples>
                <resolution>1</resolution>
                <min_angle>-1.91986</min_angle>
                <max_angle>1.91986</max_angle>
              </horizontal>
              <vertical>
                <samples>1</samples>
                <min_angle>0</min_angle>
                <max_angle>0</max_angle>
              </vertical>
            </scan>
            <range>
              <min>0.05</min>
              <max>25</max>
              <resolution>0.001</resolution>
            </range>
          </ray>
          <plugin name='gazebo_ros_sick_laser' filename='libgazebo_ros_gpu_laser.so'>
            <gaussianNoise>0.06</gaussianNoise>
            <alwaysOn>1</alwaysOn>
            <updateRate>10</updateRate>
            <topicName>scan_raw</topicName>
            <frameName>base_laser_link</frameName>
            <robotNamespace>/</robotNamespace>
          </plugin>
          <pose>0.202 0 0.0945 0 -0 0</pose>
        </sensor>
        <sensor name='base_sonar_01' type='ray'>
          <update_rate>5</update_rate>
          <visualize>0</visualize>
          <ray>
            <scan>
              <horizontal>
                <samples>5</samples>
                <resolution>1</resolution>
                <min_angle>-0.25</min_angle>
                <max_angle>0.25</max_angle>
              </horizontal>
              <vertical>
                <samples>5</samples>
                <resolution>1</resolution>
                <min_angle>-0.25</min_angle>
                <max_angle>0.25</max_angle>
              </vertical>
            </scan>
            <range>
              <min>0.02</min>
              <max>1</max>
              <resolution>0.01</resolution>
            </range>
          </ray>
          <plugin name='gazebo_ros_range' filename='libgazebo_ros_range.so'>
            <gaussianNoise>0.005</gaussianNoise>
            <alwaysOn>1</alwaysOn>
            <updateRate>5</updateRate>
            <topicName>sonar_base</topicName>
            <frameName>base_sonar_01_link</frameName>
            <minRange>0.02</minRange>
            <maxRange>1.0</maxRange>
            <fov>0.5</fov>
            <radiation>ultrasound</radiation>
            <robotNamespace>/</robotNamespace>
          </plugin>
          <pose>-0.183 -0.183 0.2715 0 -0 -2.35619</pose>
        </sensor>
        <sensor name='base_sonar_02' type='ray'>
          <update_rate>5</update_rate>
          <visualize>0</visualize>
          <ray>
            <scan>
              <horizontal>
                <samples>5</samples>
                <resolution>1</resolution>
                <min_angle>-0.25</min_angle>
                <max_angle>0.25</max_angle>
              </horizontal>
              <vertical>
                <samples>5</samples>
                <resolution>1</resolution>
                <min_angle>-0.25</min_angle>
                <max_angle>0.25</max_angle>
              </vertical>
            </scan>
            <range>
              <min>0.02</min>
              <max>1</max>
              <resolution>0.01</resolution>
            </range>
          </ray>
          <plugin name='gazebo_ros_range' filename='libgazebo_ros_range.so'>
            <gaussianNoise>0.005</gaussianNoise>
            <alwaysOn>1</alwaysOn>
            <updateRate>5</updateRate>
            <topicName>sonar_base</topicName>
            <frameName>base_sonar_02_link</frameName>
            <minRange>0.02</minRange>
            <maxRange>1.0</maxRange>
            <fov>0.5</fov>
            <radiation>ultrasound</radiation>
            <robotNamespace>/</robotNamespace>
          </plugin>
          <pose>-0.259 0 0.2715 0 -0 3.14159</pose>
        </sensor>
        <sensor name='base_sonar_03' type='ray'>
          <update_rate>5</update_rate>
          <visualize>0</visualize>
          <ray>
            <scan>
              <horizontal>
                <samples>5</samples>
                <resolution>1</resolution>
                <min_angle>-0.25</min_angle>
                <max_angle>0.25</max_angle>
              </horizontal>
              <vertical>
                <samples>5</samples>
                <resolution>1</resolution>
                <min_angle>-0.25</min_angle>
                <max_angle>0.25</max_angle>
              </vertical>
            </scan>
            <range>
              <min>0.02</min>
              <max>1</max>
              <resolution>0.01</resolution>
            </range>
          </ray>
          <plugin name='gazebo_ros_range' filename='libgazebo_ros_range.so'>
            <gaussianNoise>0.005</gaussianNoise>
            <alwaysOn>1</alwaysOn>
            <updateRate>5</updateRate>
            <topicName>sonar_base</topicName>
            <frameName>base_sonar_03_link</frameName>
            <minRange>0.02</minRange>
            <maxRange>1.0</maxRange>
            <fov>0.5</fov>
            <radiation>ultrasound</radiation>
            <robotNamespace>/</robotNamespace>
          </plugin>
          <pose>-0.183 0.183 0.2715 0 -0 2.35619</pose>
        </sensor>
        <sensor name='base_contact' type='contact'>
          <update_rate>1000</update_rate>
          <always_on>1</always_on>
          <contact>
            <collision>base_footprint_fixed_joint_lump__base_link_collision</collision>
            <topic>/bumper_contact</topic>
          </contact>
          <plugin name='gazebo_ros_bumper_controller' filename='libgazebo_ros_bumper.so'>
            <alwaysOn>1</alwaysOn>
            <updateRate>1000.0</updateRate>
            <bumperTopicName>/robot_bumper</bumperTopicName>
            <frameName>world</frameName>
          </plugin>
        </sensor>
        <self_collide>0</self_collide>
        <enable_wind>0</enable_wind>
        <kinematic>0</kinematic>
      </link>
      <joint name='caster_back_left_1_joint' type='revolute'>
        <pose relative_to='base_footprint'>-0.1735 0.102 0.065 0 -0 0</pose>
        <parent>base_footprint</parent>
        <child>caster_back_left_1_link</child>
        <axis>
          <xyz>0 0 1</xyz>
          <limit>
            <lower>-1e+16</lower>
            <upper>1e+16</upper>
          </limit>
          <dynamics>
            <damping>0.005</damping>
            <friction>0</friction>
            <spring_reference>0</spring_reference>
            <spring_stiffness>0</spring_stiffness>
          </dynamics>
        </axis>
      </joint>
      <link name='caster_back_left_1_link'>
        <pose relative_to='caster_back_left_1_joint'>0 0 0 0 -0 0</pose>
        <inertial>
          <pose>-0.006346 5.3e-05 -0.020375 0 -0 0</pose>
          <mass>0.0514476</mass>
          <inertia>
            <ixx>1.513e-05</ixx>
            <ixy>-3e-08</ixy>
            <ixz>2.67e-06</ixz>
            <iyy>1.309e-05</iyy>
            <iyz>-5e-08</iyz>
            <izz>1.198e-05</izz>
          </inertia>
        </inertial>
        <visual name='caster_back_left_1_link_visual'>
          <pose>0 0 0 0 -0 0</pose>
          <geometry>
            <mesh>
              <scale>1 1 1</scale>
              <uri>/home/adriano/Desktop/tiago_public_ws/src/pmb2_robot/pmb2_description/meshes/wheels/caster_1.stl</uri>
            </mesh>
          </geometry>
          <material>
            <script>
              <name>Gazebo/DarkGrey</name>
              <uri>file://media/materials/scripts/gazebo.material</uri>
            </script>
          </material>
        </visual>
        <self_collide>0</self_collide>
        <enable_wind>0</enable_wind>
        <kinematic>0</kinematic>
      </link>
      <joint name='caster_back_left_2_joint' type='revolute'>
        <pose relative_to='caster_back_left_1_link'>-0.016 0 -0.04 -1.5708 0 0</pose>
        <parent>caster_back_left_1_link</parent>
        <child>caster_back_left_2_link</child>
        <axis>
          <xyz>0 0 1</xyz>
          <limit>
            <lower>-1e+16</lower>
            <upper>1e+16</upper>
          </limit>
          <dynamics>
            <spring_reference>0</spring_reference>
            <spring_stiffness>0</spring_stiffness>
          </dynamics>
        </axis>
      </joint>
      <link name='caster_back_left_2_link'>
        <pose relative_to='caster_back_left_2_joint'>0 0 0 0 -0 0</pose>
        <inertial>
          <pose>0 0 0 0 -0 0</pose>
          <mass>0.0885578</mass>
          <inertia>
            <ixx>1.075e-05</ixx>
            <ixy>0</ixy>
            <ixz>0</ixz>
            <iyy>1.541e-05</iyy>
            <iyz>0</iyz>
            <izz>1.075e-05</izz>
          </inertia>
        </inertial>
        <collision name='caster_back_left_2_link_collision'>
          <pose>0 0 0 0 -0 0</pose>
          <geometry>
            <sphere>
              <radius>0.025</radius>
            </sphere>
          </geometry>
          <surface>
            <contact>
              <ode>
                <kp>1e+07</kp>
                <kd>10</kd>
                <max_vel>10</max_vel>
                <min_depth>0.0005</min_depth>
              </ode>
            </contact>
            <friction>
              <ode>
                <mu>0.1</mu>
                <mu2>0.1</mu2>
              </ode>
              <torsional>
                <ode/>
              </torsional>
            </friction>
            <bounce/>
          </surface>
          <max_contacts>10</max_contacts>
        </collision>
        <visual name='caster_back_left_2_link_visual'>
          <pose>0 0 0 0 -0 0</pose>
          <geometry>
            <mesh>
              <scale>1 1 1</scale>
              <uri>/home/adriano/Desktop/tiago_public_ws/src/pmb2_robot/pmb2_description/meshes/wheels/caster_2.stl</uri>
            </mesh>
          </geometry>
          <material>
            <script>
              <name>Gazebo/DarkGrey</name>
              <uri>file://media/materials/scripts/gazebo.material</uri>
            </script>
          </material>
        </visual>
        <self_collide>0</self_collide>
        <enable_wind>0</enable_wind>
        <kinematic>0</kinematic>
      </link>
      <joint name='caster_back_right_1_joint' type='revolute'>
        <pose relative_to='base_footprint'>-0.1735 -0.102 0.065 0 -0 0</pose>
        <parent>base_footprint</parent>
        <child>caster_back_right_1_link</child>
        <axis>
          <xyz>0 0 1</xyz>
          <limit>
            <lower>-1e+16</lower>
            <upper>1e+16</upper>
          </limit>
          <dynamics>
            <damping>0.005</damping>
            <friction>0</friction>
            <spring_reference>0</spring_reference>
            <spring_stiffness>0</spring_stiffness>
          </dynamics>
        </axis>
      </joint>
      <link name='caster_back_right_1_link'>
        <pose relative_to='caster_back_right_1_joint'>0 0 0 0 -0 0</pose>
        <inertial>
          <pose>-0.006346 5.3e-05 -0.020375 0 -0 0</pose>
          <mass>0.0514476</mass>
          <inertia>
            <ixx>1.513e-05</ixx>
            <ixy>-3e-08</ixy>
            <ixz>2.67e-06</ixz>
            <iyy>1.309e-05</iyy>
            <iyz>-5e-08</iyz>
            <izz>1.198e-05</izz>
          </inertia>
        </inertial>
        <visual name='caster_back_right_1_link_visual'>
          <pose>0 0 0 0 -0 0</pose>
          <geometry>
            <mesh>
              <scale>1 1 1</scale>
              <uri>/home/adriano/Desktop/tiago_public_ws/src/pmb2_robot/pmb2_description/meshes/wheels/caster_1.stl</uri>
            </mesh>
          </geometry>
          <material>
            <script>
              <name>Gazebo/DarkGrey</name>
              <uri>file://media/materials/scripts/gazebo.material</uri>
            </script>
          </material>
        </visual>
        <self_collide>0</self_collide>
        <enable_wind>0</enable_wind>
        <kinematic>0</kinematic>
      </link>
      <joint name='caster_back_right_2_joint' type='revolute'>
        <pose relative_to='caster_back_right_1_link'>-0.016 0 -0.04 -1.5708 0 0</pose>
        <parent>caster_back_right_1_link</parent>
        <child>caster_back_right_2_link</child>
        <axis>
          <xyz>0 0 1</xyz>
          <limit>
            <lower>-1e+16</lower>
            <upper>1e+16</upper>
          </limit>
          <dynamics>
            <spring_reference>0</spring_reference>
            <spring_stiffness>0</spring_stiffness>
          </dynamics>
        </axis>
      </joint>
      <link name='caster_back_right_2_link'>
        <pose relative_to='caster_back_right_2_joint'>0 0 0 0 -0 0</pose>
        <inertial>
          <pose>0 0 0 0 -0 0</pose>
          <mass>0.0885578</mass>
          <inertia>
            <ixx>1.075e-05</ixx>
            <ixy>0</ixy>
            <ixz>0</ixz>
            <iyy>1.541e-05</iyy>
            <iyz>0</iyz>
            <izz>1.075e-05</izz>
          </inertia>
        </inertial>
        <collision name='caster_back_right_2_link_collision'>
          <pose>0 0 0 0 -0 0</pose>
          <geometry>
            <sphere>
              <radius>0.025</radius>
            </sphere>
          </geometry>
          <surface>
            <contact>
              <ode>
                <kp>1e+07</kp>
                <kd>10</kd>
                <max_vel>10</max_vel>
                <min_depth>0.0005</min_depth>
              </ode>
            </contact>
            <friction>
              <ode>
                <mu>0.1</mu>
                <mu2>0.1</mu2>
              </ode>
              <torsional>
                <ode/>
              </torsional>
            </friction>
            <bounce/>
          </surface>
          <max_contacts>10</max_contacts>
        </collision>
        <visual name='caster_back_right_2_link_visual'>
          <pose>0 0 0 0 -0 0</pose>
          <geometry>
            <mesh>
              <scale>1 1 1</scale>
              <uri>/home/adriano/Desktop/tiago_public_ws/src/pmb2_robot/pmb2_description/meshes/wheels/caster_2.stl</uri>
            </mesh>
          </geometry>
          <material>
            <script>
              <name>Gazebo/DarkGrey</name>
              <uri>file://media/materials/scripts/gazebo.material</uri>
            </script>
          </material>
        </visual>
        <self_collide>0</self_collide>
        <enable_wind>0</enable_wind>
        <kinematic>0</kinematic>
      </link>
      <joint name='caster_front_left_1_joint' type='revolute'>
        <pose relative_to='base_footprint'>0.1695 0.102 0.065 0 -0 0</pose>
        <parent>base_footprint</parent>
        <child>caster_front_left_1_link</child>
        <axis>
          <xyz>0 0 1</xyz>
          <limit>
            <lower>-1e+16</lower>
            <upper>1e+16</upper>
          </limit>
          <dynamics>
            <damping>0.005</damping>
            <friction>0</friction>
            <spring_reference>0</spring_reference>
            <spring_stiffness>0</spring_stiffness>
          </dynamics>
        </axis>
      </joint>
      <link name='caster_front_left_1_link'>
        <pose relative_to='caster_front_left_1_joint'>0 0 0 0 -0 0</pose>
        <inertial>
          <pose>-0.006346 5.3e-05 -0.020375 0 -0 0</pose>
          <mass>0.0514476</mass>
          <inertia>
            <ixx>1.513e-05</ixx>
            <ixy>-3e-08</ixy>
            <ixz>2.67e-06</ixz>
            <iyy>1.309e-05</iyy>
            <iyz>-5e-08</iyz>
            <izz>1.198e-05</izz>
          </inertia>
        </inertial>
        <visual name='caster_front_left_1_link_visual'>
          <pose>0 0 0 0 -0 0</pose>
          <geometry>
            <mesh>
              <scale>1 1 1</scale>
              <uri>/home/adriano/Desktop/tiago_public_ws/src/pmb2_robot/pmb2_description/meshes/wheels/caster_1.stl</uri>
            </mesh>
          </geometry>
          <material>
            <script>
              <name>Gazebo/DarkGrey</name>
              <uri>file://media/materials/scripts/gazebo.material</uri>
            </script>
          </material>
        </visual>
        <self_collide>0</self_collide>
        <enable_wind>0</enable_wind>
        <kinematic>0</kinematic>
      </link>
      <joint name='caster_front_left_2_joint' type='revolute'>
        <pose relative_to='caster_front_left_1_link'>-0.016 0 -0.04 -1.5708 0 0</pose>
        <parent>caster_front_left_1_link</parent>
        <child>caster_front_left_2_link</child>
        <axis>
          <xyz>0 0 1</xyz>
          <limit>
            <lower>-1e+16</lower>
            <upper>1e+16</upper>
          </limit>
          <dynamics>
            <spring_reference>0</spring_reference>
            <spring_stiffness>0</spring_stiffness>
          </dynamics>
        </axis>
      </joint>
      <link name='caster_front_left_2_link'>
        <pose relative_to='caster_front_left_2_joint'>0 0 0 0 -0 0</pose>
        <inertial>
          <pose>0 0 0 0 -0 0</pose>
          <mass>0.0885578</mass>
          <inertia>
            <ixx>1.075e-05</ixx>
            <ixy>0</ixy>
            <ixz>0</ixz>
            <iyy>1.541e-05</iyy>
            <iyz>0</iyz>
            <izz>1.075e-05</izz>
          </inertia>
        </inertial>
        <collision name='caster_front_left_2_link_collision'>
          <pose>0 0 0 0 -0 0</pose>
          <geometry>
            <sphere>
              <radius>0.025</radius>
            </sphere>
          </geometry>
          <surface>
            <contact>
              <ode>
                <kp>1e+07</kp>
                <kd>10</kd>
                <max_vel>10</max_vel>
                <min_depth>0.0005</min_depth>
              </ode>
            </contact>
            <friction>
              <ode>
                <mu>0.1</mu>
                <mu2>0.1</mu2>
              </ode>
              <torsional>
                <ode/>
              </torsional>
            </friction>
            <bounce/>
          </surface>
          <max_contacts>10</max_contacts>
        </collision>
        <visual name='caster_front_left_2_link_visual'>
          <pose>0 0 0 0 -0 0</pose>
          <geometry>
            <mesh>
              <scale>1 1 1</scale>
              <uri>/home/adriano/Desktop/tiago_public_ws/src/pmb2_robot/pmb2_description/meshes/wheels/caster_2.stl</uri>
            </mesh>
          </geometry>
          <material>
            <script>
              <name>Gazebo/DarkGrey</name>
              <uri>file://media/materials/scripts/gazebo.material</uri>
            </script>
          </material>
        </visual>
        <self_collide>0</self_collide>
        <enable_wind>0</enable_wind>
        <kinematic>0</kinematic>
      </link>
      <joint name='caster_front_right_1_joint' type='revolute'>
        <pose relative_to='base_footprint'>0.1695 -0.102 0.065 0 -0 0</pose>
        <parent>base_footprint</parent>
        <child>caster_front_right_1_link</child>
        <axis>
          <xyz>0 0 1</xyz>
          <limit>
            <lower>-1e+16</lower>
            <upper>1e+16</upper>
          </limit>
          <dynamics>
            <damping>0.005</damping>
            <friction>0</friction>
            <spring_reference>0</spring_reference>
            <spring_stiffness>0</spring_stiffness>
          </dynamics>
        </axis>
      </joint>
      <link name='caster_front_right_1_link'>
        <pose relative_to='caster_front_right_1_joint'>0 0 0 0 -0 0</pose>
        <inertial>
          <pose>-0.006346 5.3e-05 -0.020375 0 -0 0</pose>
          <mass>0.0514476</mass>
          <inertia>
            <ixx>1.513e-05</ixx>
            <ixy>-3e-08</ixy>
            <ixz>2.67e-06</ixz>
            <iyy>1.309e-05</iyy>
            <iyz>-5e-08</iyz>
            <izz>1.198e-05</izz>
          </inertia>
        </inertial>
        <visual name='caster_front_right_1_link_visual'>
          <pose>0 0 0 0 -0 0</pose>
          <geometry>
            <mesh>
              <scale>1 1 1</scale>
              <uri>/home/adriano/Desktop/tiago_public_ws/src/pmb2_robot/pmb2_description/meshes/wheels/caster_1.stl</uri>
            </mesh>
          </geometry>
          <material>
            <script>
              <name>Gazebo/DarkGrey</name>
              <uri>file://media/materials/scripts/gazebo.material</uri>
            </script>
          </material>
        </visual>
        <self_collide>0</self_collide>
        <enable_wind>0</enable_wind>
        <kinematic>0</kinematic>
      </link>
      <joint name='caster_front_right_2_joint' type='revolute'>
        <pose relative_to='caster_front_right_1_link'>-0.016 0 -0.04 -1.5708 0 0</pose>
        <parent>caster_front_right_1_link</parent>
        <child>caster_front_right_2_link</child>
        <axis>
          <xyz>0 0 1</xyz>
          <limit>
            <lower>-1e+16</lower>
            <upper>1e+16</upper>
          </limit>
          <dynamics>
            <spring_reference>0</spring_reference>
            <spring_stiffness>0</spring_stiffness>
          </dynamics>
        </axis>
      </joint>
      <link name='caster_front_right_2_link'>
        <pose relative_to='caster_front_right_2_joint'>0 0 0 0 -0 0</pose>
        <inertial>
          <pose>0 0 0 0 -0 0</pose>
          <mass>0.0885578</mass>
          <inertia>
            <ixx>1.075e-05</ixx>
            <ixy>0</ixy>
            <ixz>0</ixz>
            <iyy>1.541e-05</iyy>
            <iyz>0</iyz>
            <izz>1.075e-05</izz>
          </inertia>
        </inertial>
        <collision name='caster_front_right_2_link_collision'>
          <pose>0 0 0 0 -0 0</pose>
          <geometry>
            <sphere>
              <radius>0.025</radius>
            </sphere>
          </geometry>
          <surface>
            <contact>
              <ode>
                <kp>1e+07</kp>
                <kd>10</kd>
                <max_vel>10</max_vel>
                <min_depth>0.0005</min_depth>
              </ode>
            </contact>
            <friction>
              <ode>
                <mu>0.1</mu>
                <mu2>0.1</mu2>
              </ode>
              <torsional>
                <ode/>
              </torsional>
            </friction>
            <bounce/>
          </surface>
          <max_contacts>10</max_contacts>
        </collision>
        <visual name='caster_front_right_2_link_visual'>
          <pose>0 0 0 0 -0 0</pose>
          <geometry>
            <mesh>
              <scale>1 1 1</scale>
              <uri>/home/adriano/Desktop/tiago_public_ws/src/pmb2_robot/pmb2_description/meshes/wheels/caster_2.stl</uri>
            </mesh>
          </geometry>
          <material>
            <script>
              <name>Gazebo/DarkGrey</name>
              <uri>file://media/materials/scripts/gazebo.material</uri>
            </script>
          </material>
        </visual>
        <self_collide>0</self_collide>
        <enable_wind>0</enable_wind>
        <kinematic>0</kinematic>
      </link>
      <joint name='suspension_left_joint' type='prismatic'>
        <pose relative_to='base_footprint'>0 0 0.0985 0 -0 0</pose>
        <parent>base_footprint</parent>
        <child>suspension_left_link</child>
        <axis>
          <xyz>0 0 1</xyz>
          <limit>
            <lower>-0.005</lower>
            <upper>0.005</upper>
            <effort>100</effort>
            <velocity>1</velocity>
          </limit>
          <dynamics>
            <damping>100</damping>
            <friction>0</friction>
            <spring_reference>0</spring_reference>
            <spring_stiffness>0</spring_stiffness>
          </dynamics>
        </axis>
      </joint>
      <link name='suspension_left_link'>
        <pose relative_to='suspension_left_joint'>0 0 0 0 -0 0</pose>
        <inertial>
          <pose>0 0 -0.02 0 -0 0</pose>
          <mass>10</mass>
          <inertia>
            <ixx>1</ixx>
            <ixy>0</ixy>
            <ixz>0</ixz>
            <iyy>1</iyy>
            <iyz>0</iyz>
            <izz>1</izz>
          </inertia>
        </inertial>
        <self_collide>0</self_collide>
        <enable_wind>0</enable_wind>
        <kinematic>0</kinematic>
      </link>
      <joint name='wheel_left_joint' type='revolute'>
        <pose relative_to='suspension_left_link'>0 0.2022 0 -1.5708 0 0</pose>
        <parent>suspension_left_link</parent>
        <child>wheel_left_link</child>
        <axis>
          <xyz>0 0 1</xyz>
          <limit>
            <effort>6</effort>
            <velocity>10.1523</velocity>
            <lower>-1e+16</lower>
            <upper>1e+16</upper>
          </limit>
          <dynamics>
            <spring_reference>0</spring_reference>
            <spring_stiffness>0</spring_stiffness>
          </dynamics>
        </axis>
      </joint>
      <link name='wheel_left_link'>
        <pose relative_to='wheel_left_joint'>0 0 0 0 -0 0</pose>
        <inertial>
          <pose>0 0 0.00207 0 -0 0</pose>
          <mass>1.82362</mass>
          <inertia>
            <ixx>0.00499743</ixx>
            <ixy>-4.464e-08</ixy>
            <ixz>-2.245e-08</ixz>
            <iyy>0.00499742</iyy>
            <iyz>1.64e-09</iyz>
            <izz>0.0083924</izz>
          </inertia>
        </inertial>
        <collision name='wheel_left_link_collision'>
          <pose>0 0 0 0 -0 0</pose>
          <geometry>
            <cylinder>
              <length>0.02</length>
              <radius>0.0985</radius>
            </cylinder>
          </geometry>
          <surface>
            <contact>
              <ode>
                <kp>1e+06</kp>
                <kd>100</kd>
                <max_vel>1</max_vel>
                <min_depth>0.002</min_depth>
              </ode>
            </contact>
            <friction>
              <ode>
                <mu>1e+14</mu>
                <mu2>1e+14</mu2>
              </ode>
              <torsional>
                <ode/>
              </torsional>
            </friction>
            <bounce/>
          </surface>
          <max_contacts>10</max_contacts>
        </collision>
        <visual name='wheel_left_link_visual'>
          <pose>0 0 0 -3.14159 0 0</pose>
          <geometry>
            <mesh>
              <scale>1 1 1</scale>
              <uri>/home/adriano/Desktop/tiago_public_ws/src/pmb2_robot/pmb2_description/meshes/wheels/wheel.stl</uri>
            </mesh>
          </geometry>
          <material>
            <script>
              <name>Gazebo/DarkGrey</name>
              <uri>file://media/materials/scripts/gazebo.material</uri>
            </script>
          </material>
        </visual>
        <self_collide>0</self_collide>
        <enable_wind>0</enable_wind>
        <kinematic>0</kinematic>
      </link>
      <joint name='suspension_right_joint' type='prismatic'>
        <pose relative_to='base_footprint'>0 0 0.0985 0 -0 0</pose>
        <parent>base_footprint</parent>
        <child>suspension_right_link</child>
        <axis>
          <xyz>0 0 1</xyz>
          <limit>
            <lower>-0.005</lower>
            <upper>0.005</upper>
            <effort>100</effort>
            <velocity>1</velocity>
          </limit>
          <dynamics>
            <damping>100</damping>
            <friction>0</friction>
            <spring_reference>0</spring_reference>
            <spring_stiffness>0</spring_stiffness>
          </dynamics>
        </axis>
      </joint>
      <link name='suspension_right_link'>
        <pose relative_to='suspension_right_joint'>0 0 0 0 -0 0</pose>
        <inertial>
          <pose>0 0 -0.02 0 -0 0</pose>
          <mass>10</mass>
          <inertia>
            <ixx>1</ixx>
            <ixy>0</ixy>
            <ixz>0</ixz>
            <iyy>1</iyy>
            <iyz>0</iyz>
            <izz>1</izz>
          </inertia>
        </inertial>
        <self_collide>0</self_collide>
        <enable_wind>0</enable_wind>
        <kinematic>0</kinematic>
      </link>
      <joint name='wheel_right_joint' type='revolute'>
        <pose relative_to='suspension_right_link'>0 -0.2022 0 -1.5708 0 0</pose>
        <parent>suspension_right_link</parent>
        <child>wheel_right_link</child>
        <axis>
          <xyz>0 0 1</xyz>
          <limit>
            <effort>6</effort>
            <velocity>10.1523</velocity>
            <lower>-1e+16</lower>
            <upper>1e+16</upper>
          </limit>
          <dynamics>
            <spring_reference>0</spring_reference>
            <spring_stiffness>0</spring_stiffness>
          </dynamics>
        </axis>
      </joint>
      <link name='wheel_right_link'>
        <pose relative_to='wheel_right_joint'>0 0 0 0 -0 0</pose>
        <inertial>
          <pose>0 0 -0.00207 0 -0 0</pose>
          <mass>1.82362</mass>
          <inertia>
            <ixx>0.00499743</ixx>
            <ixy>4.464e-08</ixy>
            <ixz>-2.245e-08</ixz>
            <iyy>0.00499742</iyy>
            <iyz>-1.64e-09</iyz>
            <izz>0.0083924</izz>
          </inertia>
        </inertial>
        <collision name='wheel_right_link_collision'>
          <pose>0 0 0 0 -0 0</pose>
          <geometry>
            <cylinder>
              <length>0.02</length>
              <radius>0.0985</radius>
            </cylinder>
          </geometry>
          <surface>
            <contact>
              <ode>
                <kp>1e+06</kp>
                <kd>100</kd>
                <max_vel>1</max_vel>
                <min_depth>0.002</min_depth>
              </ode>
            </contact>
            <friction>
              <ode>
                <mu>1e+14</mu>
                <mu2>1e+14</mu2>
              </ode>
              <torsional>
                <ode/>
              </torsional>
            </friction>
            <bounce/>
          </surface>
          <max_contacts>10</max_contacts>
        </collision>
        <visual name='wheel_right_link_visual'>
          <pose>0 0 0 0 -0 0</pose>
          <geometry>
            <mesh>
              <scale>1 1 1</scale>
              <uri>/home/adriano/Desktop/tiago_public_ws/src/pmb2_robot/pmb2_description/meshes/wheels/wheel.stl</uri>
            </mesh>
          </geometry>
          <material>
            <script>
              <name>Gazebo/DarkGrey</name>
              <uri>file://media/materials/scripts/gazebo.material</uri>
            </script>
          </material>
        </visual>
        <self_collide>0</self_collide>
        <enable_wind>0</enable_wind>
        <kinematic>0</kinematic>
      </link>
      <joint name='torso_lift_joint' type='prismatic'>
        <pose relative_to='base_footprint'>-0.062 0 0.8885 0 -0 0</pose>
        <parent>base_footprint</parent>
        <child>torso_lift_link</child>
        <axis>
          <xyz>0 0 1</xyz>
          <limit>
            <lower>0</lower>
            <upper>0.35</upper>
            <effort>2000</effort>
            <velocity>0.07</velocity>
          </limit>
          <dynamics>
            <damping>1000</damping>
            <friction>0</friction>
            <spring_reference>0</spring_reference>
            <spring_stiffness>0</spring_stiffness>
          </dynamics>
        </axis>
      </joint>
      <link name='torso_lift_link'>
        <pose relative_to='torso_lift_joint'>0 0 0 0 -0 0</pose>
        <inertial>
          <pose>0.04361 -0.00116 -0.17334 0 -0 0</pose>
          <mass>6.93198</mass>
          <inertia>
            <ixx>0.24487</ixx>
            <ixy>-0.001456</ixy>
            <ixz>-0.009742</ixz>
            <iyy>0.249269</iyy>
            <iyz>0.008281</iyz>
            <izz>0.090395</izz>
          </inertia>
        </inertial>
        <collision name='torso_lift_link_collision'>
          <pose>0 0 0 0 -0 0</pose>
          <geometry>
            <mesh>
              <scale>1 1 1</scale>
              <uri>/home/adriano/Desktop/tiago_public_ws/src/tiago_robot/tiago_description/meshes/torso/torso_lift_collision_core.dae</uri>
            </mesh>
          </geometry>
          <max_contacts>10</max_contacts>
          <surface>
            <contact>
              <ode/>
            </contact>
            <bounce/>
            <friction>
              <torsional>
                <ode/>
              </torsional>
              <ode/>
            </friction>
          </surface>
        </collision>
        <collision name='torso_lift_link_collision_1'>
          <pose>0 0 0 0 -0 0</pose>
          <geometry>
            <mesh>
              <scale>1 1 1</scale>
              <uri>/home/adriano/Desktop/tiago_public_ws/src/tiago_robot/tiago_description/meshes/torso/torso_lift_collision_shoulder.dae</uri>
            </mesh>
          </geometry>
          <max_contacts>10</max_contacts>
          <surface>
            <contact>
              <ode/>
            </contact>
            <bounce/>
            <friction>
              <torsional>
                <ode/>
              </torsional>
              <ode/>
            </friction>
          </surface>
        </collision>
        <collision name='torso_lift_link_collision_2'>
          <pose>0 0 0 0 -0 0</pose>
          <geometry>
            <mesh>
              <scale>1 1 1</scale>
              <uri>/home/adriano/Desktop/tiago_public_ws/src/tiago_robot/tiago_description/meshes/torso/torso_lift_collision_neck.dae</uri>
            </mesh>
          </geometry>
          <max_contacts>10</max_contacts>
          <surface>
            <contact>
              <ode/>
            </contact>
            <bounce/>
            <friction>
              <torsional>
                <ode/>
              </torsional>
              <ode/>
            </friction>
          </surface>
        </collision>
        <visual name='torso_lift_link_visual'>
          <pose>0 0 0 0 -0 0</pose>
          <geometry>
            <mesh>
              <scale>1 1 1</scale>
              <uri>/home/adriano/Desktop/tiago_public_ws/src/tiago_robot/tiago_description/meshes/torso/torso_lift_with_arm.stl</uri>
            </mesh>
          </geometry>
        </visual>
        <self_collide>0</self_collide>
        <enable_wind>0</enable_wind>
        <kinematic>0</kinematic>
        <sensor name='torso_contact' type='contact'>
          <update_rate>1000</update_rate>
          <always_on>1</always_on>
          <contact>
            <collision>torso_lift_link_collision</collision>
            <topic>/bumper_contact/torso_lift_link</topic>
          </contact>
          <plugin name='gazebo_ros_bumper_controller' filename='libgazebo_ros_bumper.so'>
            <alwaysOn>1</alwaysOn>
            <updateRate>1000.0</updateRate>
            <bumperTopicName>/robot_bumper</bumperTopicName>
            <frameName>world</frameName>
          </plugin>
        </sensor>
      </link>
      <joint name='arm_1_joint' type='revolute'>
        <pose relative_to='torso_lift_link'>0.15505 0.014 -0.151 0 0 -1.5708</pose>
        <parent>torso_lift_link</parent>
        <child>arm_1_link</child>
        <axis>
          <xyz>0 0 1</xyz>
          <limit>
            <lower>0</lower>
            <upper>2.74889</upper>
            <effort>43</effort>
            <velocity>1.95</velocity>
          </limit>
          <dynamics>
            <damping>1</damping>
            <friction>1</friction>
            <spring_reference>0</spring_reference>
            <spring_stiffness>0</spring_stiffness>
          </dynamics>
        </axis>
        <physics>
          <ode>
            <implicit_spring_damper>1</implicit_spring_damper>
            <cfm_damping>1</cfm_damping>
            <limit>
              <cfm>0</cfm>
              <erp>0.2</erp>
            </limit>
          </ode>
        </physics>
      </joint>
      <link name='arm_1_link'>
        <pose relative_to='arm_1_joint'>0 0 0 0 -0 0</pose>
        <inertial>
          <pose>0.061191 -0.022397 -0.012835 0 -0 0</pose>
          <mass>1.56343</mass>
          <inertia>
            <ixx>0.002471</ixx>
            <ixy>-0.001809</ixy>
            <ixz>-0.001202</ixz>
            <iyy>0.006132</iyy>
            <iyz>0.000494</iyz>
            <izz>0.006704</izz>
          </inertia>
        </inertial>
        <collision name='arm_1_link_collision'>
          <pose>0 0 0 0 -0 0</pose>
          <geometry>
            <mesh>
              <scale>1 1 1</scale>
              <uri>/home/adriano/Desktop/tiago_public_ws/src/tiago_robot/tiago_description/meshes/arm/arm_1_collision.dae</uri>
            </mesh>
          </geometry>
          <surface>
            <contact>
              <ode/>
            </contact>
            <friction>
              <ode>
                <mu>0.9</mu>
                <mu2>0.9</mu2>
              </ode>
              <torsional>
                <ode/>
              </torsional>
            </friction>
            <bounce/>
          </surface>
          <max_contacts>10</max_contacts>
        </collision>
        <visual name='arm_1_link_visual'>
          <pose>0 0 0 0 -0 0</pose>
          <geometry>
            <mesh>
              <scale>1 1 1</scale>
              <uri>/home/adriano/Desktop/tiago_public_ws/src/tiago_robot/tiago_description/meshes/arm/arm_1.stl</uri>
            </mesh>
          </geometry>
          <material>
            <script>
              <name>Gazebo/DarkGrey</name>
              <uri>file://media/materials/scripts/gazebo.material</uri>
            </script>
          </material>
        </visual>
        <sensor name='arm_1_contact' type='contact'>
          <update_rate>1000</update_rate>
          <always_on>1</always_on>
          <contact>
            <collision>arm_1_link_collision</collision>
            <topic>/bumper_contact/arm_1_link</topic>
          </contact>
          <plugin name='gazebo_ros_bumper_controller' filename='libgazebo_ros_bumper.so'>
            <alwaysOn>1</alwaysOn>
            <updateRate>1000.0</updateRate>
            <bumperTopicName>/robot_bumper</bumperTopicName>
            <frameName>world</frameName>
          </plugin>
        </sensor>
        <self_collide>0</self_collide>
        <enable_wind>0</enable_wind>
        <kinematic>0</kinematic>
      </link>
      <joint name='arm_2_joint' type='revolute'>
        <pose relative_to='arm_1_link'>0.125 0.0195 -0.031 1.5708 -0 0</pose>
        <parent>arm_1_link</parent>
        <child>arm_2_link</child>
        <axis>
          <xyz>0 0 1</xyz>
          <limit>
            <lower>-1.5708</lower>
            <upper>1.09083</upper>
            <effort>43</effort>
            <velocity>1.95</velocity>
          </limit>
          <dynamics>
            <damping>1</damping>
            <friction>1</friction>
            <spring_reference>0</spring_reference>
            <spring_stiffness>0</spring_stiffness>
          </dynamics>
        </axis>
        <physics>
          <ode>
            <implicit_spring_damper>1</implicit_spring_damper>
            <cfm_damping>1</cfm_damping>
            <limit>
              <cfm>0</cfm>
              <erp>0.2</erp>
            </limit>
          </ode>
        </physics>
      </joint>
      <link name='arm_2_link'>
        <pose relative_to='arm_2_joint'>0 0 0 0 -0 0</pose>
        <inertial>
          <pose>0.030432 0.000229 -0.005942 0 -0 0</pose>
          <mass>1.8004</mass>
          <inertia>
            <ixx>0.001809</ixx>
            <ixy>1.5e-05</ixy>
            <ixz>0.000254</ixz>
            <iyy>0.004333</iyy>
            <iyz>1.4e-05</iyz>
            <izz>0.004341</izz>
          </inertia>
        </inertial>
        <collision name='arm_2_link_collision'>
          <pose>0 0 0 0 -0 0</pose>
          <geometry>
            <mesh>
              <scale>1 1 1</scale>
              <uri>/home/adriano/Desktop/tiago_public_ws/src/tiago_robot/tiago_description/meshes/arm/arm_2_collision.dae</uri>
            </mesh>
          </geometry>
          <surface>
            <contact>
              <ode/>
            </contact>
            <friction>
              <ode>
                <mu>0.9</mu>
                <mu2>0.9</mu2>
              </ode>
              <torsional>
                <ode/>
              </torsional>
            </friction>
            <bounce/>
          </surface>
          <max_contacts>10</max_contacts>
        </collision>
        <visual name='arm_2_link_visual'>
          <pose>0 0 0 0 -0 0</pose>
          <geometry>
            <mesh>
              <scale>1 1 1</scale>
              <uri>/home/adriano/Desktop/tiago_public_ws/src/tiago_robot/tiago_description/meshes/arm/arm_2.stl</uri>
            </mesh>
          </geometry>
          <material>
            <script>
              <name>Gazebo/DarkGrey</name>
              <uri>file://media/materials/scripts/gazebo.material</uri>
            </script>
          </material>
        </visual>
        <sensor name='arm_2_contact' type='contact'>
          <update_rate>1000</update_rate>
          <always_on>1</always_on>
          <contact>
            <collision>arm_2_link_collision</collision>
            <topic>/bumper_contact/arm_2_link</topic>
          </contact>
          <plugin name='gazebo_ros_bumper_controller' filename='libgazebo_ros_bumper.so'>
            <alwaysOn>1</alwaysOn>
            <updateRate>1000.0</updateRate>
            <bumperTopicName>/robot_bumper</bumperTopicName>
            <frameName>world</frameName>
          </plugin>
        </sensor>
        <self_collide>0</self_collide>
        <enable_wind>0</enable_wind>
        <kinematic>0</kinematic>
      </link>
      <joint name='arm_3_joint' type='revolute'>
        <pose relative_to='arm_2_link'>0.0895 0 -0.0015 -1.5708 0 1.5708</pose>
        <parent>arm_2_link</parent>
        <child>arm_3_link</child>
        <axis>
          <xyz>0 0 1</xyz>
          <limit>
            <lower>-3.53429</lower>
            <upper>1.5708</upper>
            <effort>26</effort>
            <velocity>2.35</velocity>
          </limit>
          <dynamics>
            <damping>1</damping>
            <friction>1</friction>
            <spring_reference>0</spring_reference>
            <spring_stiffness>0</spring_stiffness>
          </dynamics>
        </axis>
        <physics>
          <ode>
            <implicit_spring_damper>1</implicit_spring_damper>
            <cfm_damping>1</cfm_damping>
            <limit>
              <cfm>0</cfm>
              <erp>0.2</erp>
            </limit>
          </ode>
        </physics>
      </joint>
      <link name='arm_3_link'>
        <pose relative_to='arm_3_joint'>0 0 0 0 -0 0</pose>
        <inertial>
          <pose>0.007418 -0.004361 -0.134194 0 -0 0</pose>
          <mass>1.8</mass>
          <inertia>
            <ixx>0.019541</ixx>
            <ixy>-0.000105</ixy>
            <ixz>-0.001717</ixz>
            <iyy>0.019936</iyy>
            <iyz>0.000852</iyz>
            <izz>0.002864</izz>
          </inertia>
        </inertial>
        <collision name='arm_3_link_collision'>
          <pose>0 0 0 0 -0 0</pose>
          <geometry>
            <mesh>
              <scale>1 1 1</scale>
              <uri>/home/adriano/Desktop/tiago_public_ws/src/tiago_robot/tiago_description/meshes/arm/arm_3_collision.dae</uri>
            </mesh>
          </geometry>
          <surface>
            <contact>
              <ode/>
            </contact>
            <friction>
              <ode>
                <mu>0.9</mu>
                <mu2>0.9</mu2>
              </ode>
              <torsional>
                <ode/>
              </torsional>
            </friction>
            <bounce/>
          </surface>
          <max_contacts>10</max_contacts>
        </collision>
        <visual name='arm_3_link_visual'>
          <pose>0 0 0 0 -0 0</pose>
          <geometry>
            <mesh>
              <scale>1 1 1</scale>
              <uri>/home/adriano/Desktop/tiago_public_ws/src/tiago_robot/tiago_description/meshes/arm/arm_3.stl</uri>
            </mesh>
          </geometry>
          <material>
            <script>
              <name>Gazebo/DarkGrey</name>
              <uri>file://media/materials/scripts/gazebo.material</uri>
            </script>
          </material>
        </visual>
        <sensor name='arm_3_contact' type='contact'>
          <update_rate>1000</update_rate>
          <always_on>1</always_on>
          <contact>
            <collision>arm_3_link_collision</collision>
            <topic>/bumper_contact/arm_3_link</topic>
          </contact>
          <plugin name='gazebo_ros_bumper_controller' filename='libgazebo_ros_bumper.so'>
            <alwaysOn>1</alwaysOn>
            <updateRate>1000.0</updateRate>
            <bumperTopicName>/robot_bumper</bumperTopicName>
            <frameName>world</frameName>
          </plugin>
        </sensor>
        <self_collide>0</self_collide>
        <enable_wind>0</enable_wind>
        <kinematic>0</kinematic>
      </link>
      <joint name='arm_4_joint' type='revolute'>
        <pose relative_to='arm_3_link'>-0.02 -0.027 -0.222 1.57079 -1.57079 3.14159</pose>
        <parent>arm_3_link</parent>
        <child>arm_4_link</child>
        <axis>
          <xyz>0 0 1</xyz>
          <limit>
            <lower>-0.392699</lower>
            <upper>2.35619</upper>
            <effort>26</effort>
            <velocity>2.35</velocity>
          </limit>
          <dynamics>
            <damping>1</damping>
            <friction>1</friction>
            <spring_reference>0</spring_reference>
            <spring_stiffness>0</spring_stiffness>
          </dynamics>
        </axis>
        <physics>
          <ode>
            <implicit_spring_damper>1</implicit_spring_damper>
            <cfm_damping>1</cfm_damping>
            <limit>
              <cfm>0</cfm>
              <erp>0.2</erp>
            </limit>
          </ode>
        </physics>
      </joint>
      <link name='arm_4_link'>
        <pose relative_to='arm_4_joint'>0 0 0 0 -0 0</pose>
        <inertial>
          <pose>-0.095658 0.014666 0.018133 0 -0 0</pose>
          <mass>1.4327</mass>
          <inertia>
            <ixx>0.00204</ixx>
            <ixy>0.000725</ixy>
            <ixz>-0.00115</ixz>
            <iyy>0.008424</iyy>
            <iyz>-0.000204</iyz>
            <izz>0.008686</izz>
          </inertia>
        </inertial>
        <collision name='arm_4_link_collision'>
          <pose>0 0 0 0 -0 0</pose>
          <geometry>
            <mesh>
              <scale>1 1 1</scale>
              <uri>/home/adriano/Desktop/tiago_public_ws/src/tiago_robot/tiago_description/meshes/arm/arm_4_collision.dae</uri>
            </mesh>
          </geometry>
          <surface>
            <contact>
              <ode/>
            </contact>
            <friction>
              <ode>
                <mu>0.9</mu>
                <mu2>0.9</mu2>
              </ode>
              <torsional>
                <ode/>
              </torsional>
            </friction>
            <bounce/>
          </surface>
          <max_contacts>10</max_contacts>
        </collision>
        <visual name='arm_4_link_visual'>
          <pose>0 0 0 0 -0 0</pose>
          <geometry>
            <mesh>
              <scale>1 1 1</scale>
              <uri>/home/adriano/Desktop/tiago_public_ws/src/tiago_robot/tiago_description/meshes/arm/arm_4.stl</uri>
            </mesh>
          </geometry>
          <material>
            <script>
              <name>Gazebo/DarkGrey</name>
              <uri>file://media/materials/scripts/gazebo.material</uri>
            </script>
          </material>
        </visual>
        <sensor name='arm_4_contact' type='contact'>
          <update_rate>1000</update_rate>
          <always_on>1</always_on>
          <contact>
            <collision>arm_4_link_collision</collision>
            <topic>/bumper_contact/arm_4_link</topic>
          </contact>
          <plugin name='gazebo_ros_bumper_controller' filename='libgazebo_ros_bumper.so'>
            <alwaysOn>1</alwaysOn>
            <updateRate>1000.0</updateRate>
            <bumperTopicName>/robot_bumper</bumperTopicName>
            <frameName>world</frameName>
          </plugin>
        </sensor>
        <self_collide>0</self_collide>
        <enable_wind>0</enable_wind>
        <kinematic>0</kinematic>
      </link>
      <joint name='arm_5_joint' type='revolute'>
        <pose relative_to='arm_4_link'>-0.162 0.02 0.027 3.14159 -1.57079 3.14159</pose>
        <parent>arm_4_link</parent>
        <child>arm_5_link</child>
        <axis>
          <xyz>0 0 1</xyz>
          <limit>
            <lower>-2.0944</lower>
            <upper>2.0944</upper>
            <effort>3</effort>
            <velocity>1.95</velocity>
          </limit>
          <dynamics>
            <damping>1</damping>
            <friction>1</friction>
            <spring_reference>0</spring_reference>
            <spring_stiffness>0</spring_stiffness>
          </dynamics>
        </axis>
        <physics>
          <ode>
            <implicit_spring_damper>1</implicit_spring_damper>
            <cfm_damping>1</cfm_damping>
            <limit>
              <cfm>0</cfm>
              <erp>0.2</erp>
            </limit>
          </ode>
        </physics>
      </joint>
      <link name='arm_5_link'>
        <pose relative_to='arm_5_joint'>0 0 0 0 -0 0</pose>
        <inertial>
          <pose>0.001078 -0.000151 -0.077173 0 -0 0</pose>
          <mass>0.935914</mass>
          <inertia>
            <ixx>0.00103619</ixx>
            <ixy>1.06223e-07</ixy>
            <ixz>1.99203e-06</ixz>
            <iyy>0.000794527</iyy>
            <iyz>-2.56396e-07</iyz>
            <izz>0.000439831</izz>
          </inertia>
        </inertial>
        <collision name='arm_5_link_collision'>
          <pose>0 0 0 0 -0 0</pose>
          <geometry>
            <mesh>
              <scale>1 1 1</scale>
              <uri>/home/adriano/Desktop/tiago_public_ws/src/tiago_robot/tiago_description/meshes/arm/arm_5_collision-wrist-2017.dae</uri>
            </mesh>
          </geometry>
          <surface>
            <contact>
              <ode/>
            </contact>
            <friction>
              <ode>
                <mu>0.9</mu>
                <mu2>0.9</mu2>
              </ode>
              <torsional>
                <ode/>
              </torsional>
            </friction>
            <bounce/>
          </surface>
          <max_contacts>10</max_contacts>
        </collision>
        <visual name='arm_5_link_visual'>
          <pose>0 0 0 0 -0 0</pose>
          <geometry>
            <mesh>
              <scale>1 1 1</scale>
              <uri>/home/adriano/Desktop/tiago_public_ws/src/tiago_robot/tiago_description/meshes/arm/arm_5-wrist-2017.stl</uri>
            </mesh>
          </geometry>
        </visual>
        <sensor name='arm_5_contact' type='contact'>
          <update_rate>1000</update_rate>
          <always_on>1</always_on>
          <contact>
            <collision>arm_5_link_collision</collision>
            <topic>/bumper_contact/arm_5_link</topic>
          </contact>
          <plugin name='gazebo_ros_bumper_controller' filename='libgazebo_ros_bumper.so'>
            <alwaysOn>1</alwaysOn>
            <updateRate>1000.0</updateRate>
            <bumperTopicName>/robot_bumper</bumperTopicName>
            <frameName>world</frameName>
          </plugin>
        </sensor>
        <self_collide>0</self_collide>
        <enable_wind>0</enable_wind>
        <kinematic>0</kinematic>
      </link>
      <joint name='arm_6_joint' type='revolute'>
        <pose relative_to='arm_5_link'>0 0 0.15 1.57079 -1.57079 3.14159</pose>
        <parent>arm_5_link</parent>
        <child>arm_6_link</child>
        <axis>
          <xyz>0 0 1</xyz>
          <limit>
            <lower>-1.41372</lower>
            <upper>1.41372</upper>
            <effort>6.6</effort>
            <velocity>1.76</velocity>
          </limit>
          <dynamics>
            <damping>1</damping>
            <friction>1</friction>
            <spring_reference>0</spring_reference>
            <spring_stiffness>0</spring_stiffness>
          </dynamics>
        </axis>
        <physics>
          <ode>
            <implicit_spring_damper>1</implicit_spring_damper>
            <cfm_damping>1</cfm_damping>
            <limit>
              <cfm>0</cfm>
              <erp>0.2</erp>
            </limit>
          </ode>
        </physics>
      </joint>
      <link name='arm_6_link'>
        <pose relative_to='arm_6_joint'>0 0 0 0 -0 0</pose>
        <inertial>
          <pose>-0.000153 -0.003122 0.000183 0 -0 0</pose>
          <mass>0.302758</mass>
          <inertia>
            <ixx>3.29234e-05</ixx>
            <ixy>6.31537e-08</ixy>
            <ixz>-4.56712e-11</ixz>
            <iyy>3.85334e-05</iyy>
            <iyz>-2.01613e-07</iyz>
            <izz>3.33283e-05</izz>
          </inertia>
        </inertial>
        <collision name='arm_6_link_collision'>
          <pose>0 0 0 0 -0 0</pose>
          <geometry>
            <mesh>
              <scale>1 1 1</scale>
              <uri>/home/adriano/Desktop/tiago_public_ws/src/tiago_robot/tiago_description/meshes/arm/arm_6_collision-wrist-2017.dae</uri>
            </mesh>
          </geometry>
          <surface>
            <contact>
              <ode/>
            </contact>
            <friction>
              <ode>
                <mu>0.9</mu>
                <mu2>0.9</mu2>
              </ode>
              <torsional>
                <ode/>
              </torsional>
            </friction>
            <bounce/>
          </surface>
          <max_contacts>10</max_contacts>
        </collision>
        <visual name='arm_6_link_visual'>
          <pose>0 0 0 0 -0 0</pose>
          <geometry>
            <mesh>
              <scale>1 1 1</scale>
              <uri>/home/adriano/Desktop/tiago_public_ws/src/tiago_robot/tiago_description/meshes/arm/arm_6-wrist-2017.stl</uri>
            </mesh>
          </geometry>
        </visual>
        <sensor name='arm_6_contact' type='contact'>
          <update_rate>1000</update_rate>
          <always_on>1</always_on>
          <contact>
            <collision>arm_6_link_collision</collision>
            <topic>/bumper_contact/arm_6_link</topic>
          </contact>
          <plugin name='gazebo_ros_bumper_controller' filename='libgazebo_ros_bumper.so'>
            <alwaysOn>1</alwaysOn>
            <updateRate>1000.0</updateRate>
            <bumperTopicName>/robot_bumper</bumperTopicName>
            <frameName>world</frameName>
          </plugin>
        </sensor>
        <self_collide>0</self_collide>
        <enable_wind>0</enable_wind>
        <kinematic>0</kinematic>
      </link>
      <joint name='arm_7_joint' type='revolute'>
        <pose relative_to='arm_6_link'>0 0 0 1.5708 -0 1.5708</pose>
        <parent>arm_6_link</parent>
        <child>arm_7_link</child>
        <axis>
          <xyz>0 0 1</xyz>
          <limit>
            <lower>-2.0944</lower>
            <upper>2.0944</upper>
            <effort>6.6</effort>
            <velocity>1.76</velocity>
          </limit>
          <dynamics>
            <damping>1</damping>
            <friction>1</friction>
            <spring_reference>0</spring_reference>
            <spring_stiffness>0</spring_stiffness>
          </dynamics>
        </axis>
        <physics>
          <provide_feedback>1</provide_feedback>
          <ode>
            <implicit_spring_damper>1</implicit_spring_damper>
            <cfm_damping>1</cfm_damping>
            <limit>
              <cfm>0</cfm>
              <erp>0.2</erp>
            </limit>
            <provide_feedback>1</provide_feedback>
          </ode>
        </physics>
      </joint>
      <link name='arm_7_link'>
        <pose relative_to='arm_7_joint'>0 0 0 0 -0 0</pose>
        <inertial>
          <pose>-0.000174 0.000176 0.081735 0 -0 0</pose>
          <mass>1.00276</mass>
          <inertia>
            <ixx>0.00257837</ixx>
            <ixy>4.28817e-05</ixy>
            <ixz>4.99285e-06</ixz>
            <iyy>0.0022625</iyy>
            <iyz>-4.9926e-06</iyz>
            <izz>0.000746465</izz>
          </inertia>
        </inertial>
        <collision name='arm_7_link_fixed_joint_lump__arm_tool_link_collision'>
          <pose>-0 0 0.047 0 -0 -1.5708</pose>
          <geometry>
            <cylinder>
              <length>0.005</length>
              <radius>0.005</radius>
            </cylinder>
          </geometry>
          <max_contacts>10</max_contacts>
          <surface>
            <contact>
              <ode/>
            </contact>
            <bounce/>
            <friction>
              <torsional>
                <ode/>
              </torsional>
              <ode/>
            </friction>
          </surface>
        </collision>
        <collision name='arm_7_link_fixed_joint_lump__wrist_ft_link_collision_1'>
          <pose>-0 0 0.05385 -0 -0 -0</pose>
          <geometry>
            <cylinder>
              <length>0.0157</length>
              <radius>0.0225</radius>
            </cylinder>
          </geometry>
          <max_contacts>10</max_contacts>
          <surface>
            <contact>
              <ode/>
            </contact>
            <bounce/>
            <friction>
              <torsional>
                <ode/>
              </torsional>
              <ode/>
            </friction>
          </surface>
        </collision>
        <collision name='arm_7_link_fixed_joint_lump__wrist_ft_tool_link_collision_2'>
          <pose>-0 0 0.066575 0 -0 -1.5708</pose>
          <geometry>
            <cylinder>
              <length>0.00975</length>
              <radius>0.025</radius>
            </cylinder>
          </geometry>
          <max_contacts>10</max_contacts>
          <surface>
            <contact>
              <ode/>
            </contact>
            <bounce/>
            <friction>
              <torsional>
                <ode/>
              </torsional>
              <ode/>
            </friction>
          </surface>
        </collision>
        <collision name='arm_7_link_fixed_joint_lump__gripper_link_collision_3'>
          <pose>-0 0 0.076575 3.14159 -0 -1.5708</pose>
          <geometry>
            <mesh>
              <scale>1 1 1</scale>
              <uri>/home/adriano/Desktop/tiago_public_ws/src/pal_gripper/pal_gripper_description/meshes/gripper_link_collision.stl</uri>
            </mesh>
          </geometry>
          <surface>
            <contact>
              <ode/>
            </contact>
            <friction>
              <ode/>
              <torsional>
                <ode/>
              </torsional>
            </friction>
            <bounce/>
          </surface>
          <max_contacts>10</max_contacts>
        </collision>
        <visual name='arm_7_link_fixed_joint_lump__arm_tool_link_visual'>
          <pose>-0 0 0.047 0 -0 -1.5708</pose>
          <geometry>
            <cylinder>
              <length>0.005</length>
              <radius>0.005</radius>
            </cylinder>
          </geometry>
        </visual>
        <visual name='arm_7_link_fixed_joint_lump__wrist_ft_link_visual_1'>
          <pose>-0 0 0.05385 -0 -0 -0</pose>
          <geometry>
            <cylinder>
              <length>0.0157</length>
              <radius>0.0225</radius>
            </cylinder>
          </geometry>
        </visual>
        <visual name='arm_7_link_fixed_joint_lump__wrist_ft_tool_link_visual_2'>
          <pose>-0 0 0.066575 0 -0 -1.5708</pose>
          <geometry>
            <cylinder>
              <length>0.00975</length>
              <radius>0.025</radius>
            </cylinder>
          </geometry>
        </visual>
        <visual name='arm_7_link_fixed_joint_lump__gripper_link_visual_3'>
          <pose>-0 0 0.076575 3.14159 -0 -1.5708</pose>
          <geometry>
            <mesh>
              <scale>1 1 1</scale>
              <uri>/home/adriano/Desktop/tiago_public_ws/src/pal_gripper/pal_gripper_description/meshes/gripper_link.stl</uri>
            </mesh>
          </geometry>
          <material>
            <script>
              <name>Gazebo/White</name>
              <uri>file://media/materials/scripts/gazebo.material</uri>
            </script>
          </material>
        </visual>
        <self_collide>0</self_collide>
        <enable_wind>0</enable_wind>
        <kinematic>0</kinematic>
      </link>
      <joint name='gripper_left_finger_joint' type='prismatic'>
        <pose relative_to='arm_7_link'>-0 0 0.076575 3.14159 -0 -1.5708</pose>
        <parent>arm_7_link</parent>
        <child>gripper_left_finger_link</child>
        <axis>
          <xyz>-1 0 0</xyz>
          <limit>
            <lower>0</lower>
            <upper>0.045</upper>
            <effort>64</effort>
            <velocity>0.05</velocity>
          </limit>
          <dynamics>
            <damping>1</damping>
            <friction>0</friction>
            <spring_reference>0</spring_reference>
            <spring_stiffness>0</spring_stiffness>
          </dynamics>
        </axis>
        <physics>
          <provide_feedback>1</provide_feedback>
          <ode>
            <implicit_spring_damper>1</implicit_spring_damper>
            <cfm_damping>1</cfm_damping>
            <limit>
              <cfm>0</cfm>
              <erp>0.2</erp>
            </limit>
            <provide_feedback>1</provide_feedback>
          </ode>
        </physics>
      </joint>
      <link name='gripper_left_finger_link'>
        <pose relative_to='gripper_left_finger_joint'>0 0 0 0 -0 0</pose>
        <inertial>
          <pose>-0.00447 0.010766 -0.121013 0 -0 0</pose>
          <mass>0.10998</mass>
          <inertia>
            <ixx>0.000232</ixx>
            <ixy>-5e-06</ixy>
            <ixz>-3.2e-05</ixz>
            <iyy>0.000224</iyy>
            <iyz>3.6e-05</iyz>
            <izz>2.9e-05</izz>
          </inertia>
        </inertial>
        <collision name='gripper_left_finger_link_collision'>
          <pose>-0.005 0 -0.165 0 -0 3.1415</pose>
          <geometry>
            <box>
              <size>0.01 0.05 0.11</size>
            </box>
          </geometry>
          <surface>
            <friction>
              <torsional>
                <coefficient>1000</coefficient>
                <use_patch_radius>1</use_patch_radius>
                <patch_radius>0.1</patch_radius>
                <ode/>
              </torsional>
              <ode>
                <mu>inf</mu>
                <mu2>inf</mu2>
                <fdir1>1 0 0</fdir1>
              </ode>
            </friction>
            <contact>
              <poissons_ratio>1</poissons_ratio>
              <elastic_modulus>inf</elastic_modulus>
              <ode>
                <kp>inf</kp>
                <kd>100</kd>
                <max_vel>0</max_vel>
                <min_depth>0.002</min_depth>
              </ode>
            </contact>
            <bounce/>
          </surface>
          <max_contacts>100</max_contacts>
        </collision>
        <visual name='gripper_left_finger_link_visual'>
          <pose>0 0 0 0 -0 3.1415</pose>
          <geometry>
            <mesh>
              <scale>1 1 1</scale>
              <uri>/home/adriano/Desktop/tiago_public_ws/src/pal_gripper/pal_gripper_description/meshes/gripper_finger_link.stl</uri>
            </mesh>
          </geometry>
          <material>
            <script>
              <name>Gazebo/Black</name>
              <uri>file://media/materials/scripts/gazebo.material</uri>
            </script>
          </material>
        </visual>
        <self_collide>0</self_collide>
        <enable_wind>0</enable_wind>
        <kinematic>0</kinematic>
      </link>
      <joint name='gripper_right_finger_joint' type='prismatic'>
        <pose relative_to='arm_7_link'>-0 0 0.076575 3.14159 -0 -1.5708</pose>
        <parent>arm_7_link</parent>
        <child>gripper_right_finger_link</child>
        <axis>
          <xyz>1 0 0</xyz>
          <limit>
            <lower>0</lower>
            <upper>0.045</upper>
            <effort>64</effort>
            <velocity>0.05</velocity>
          </limit>
          <dynamics>
            <damping>1</damping>
            <friction>0</friction>
            <spring_reference>0</spring_reference>
            <spring_stiffness>0</spring_stiffness>
          </dynamics>
        </axis>
        <physics>
          <provide_feedback>1</provide_feedback>
          <ode>
            <implicit_spring_damper>1</implicit_spring_damper>
            <cfm_damping>1</cfm_damping>
            <limit>
              <cfm>0</cfm>
              <erp>0.2</erp>
            </limit>
            <provide_feedback>1</provide_feedback>
          </ode>
        </physics>
      </joint>
      <link name='gripper_right_finger_link'>
        <pose relative_to='gripper_right_finger_joint'>0 0 0 0 -0 0</pose>
        <inertial>
          <pose>-0.00447 0.010766 -0.121013 0 -0 0</pose>
          <mass>0.10998</mass>
          <inertia>
            <ixx>0.000232</ixx>
            <ixy>-5e-06</ixy>
            <ixz>-3.2e-05</ixz>
            <iyy>0.000224</iyy>
            <iyz>3.6e-05</iyz>
            <izz>2.9e-05</izz>
          </inertia>
        </inertial>
        <collision name='gripper_right_finger_link_collision'>
          <pose>0.005 0 -0.165 0 -0 3.1415</pose>
          <geometry>
            <box>
              <size>0.01 0.05 0.11</size>
            </box>
          </geometry>
          <surface>
            <friction>
              <torsional>
                <coefficient>1000</coefficient>
                <use_patch_radius>1</use_patch_radius>
                <patch_radius>0.1</patch_radius>
                <ode/>
              </torsional>
              <ode>
                <mu>inf</mu>
                <mu2>inf</mu2>
                <fdir1>1 0 0</fdir1>
              </ode>
            </friction>
            <contact>
              <poissons_ratio>1</poissons_ratio>
              <elastic_modulus>inf</elastic_modulus>
              <ode>
                <kp>inf</kp>
                <kd>100</kd>
                <max_vel>0</max_vel>
                <min_depth>0.002</min_depth>
              </ode>
            </contact>
            <bounce/>
          </surface>
          <max_contacts>100</max_contacts>
        </collision>
        <visual name='gripper_right_finger_link_visual'>
          <pose>0 0 0 0 -0 3.1415</pose>
          <geometry>
            <mesh>
              <scale>-1 -1 1</scale>
              <uri>/home/adriano/Desktop/tiago_public_ws/src/pal_gripper/pal_gripper_description/meshes/gripper_finger_link.stl</uri>
            </mesh>
          </geometry>
          <material>
            <script>
              <name>Gazebo/Black</name>
              <uri>file://media/materials/scripts/gazebo.material</uri>
            </script>
          </material>
        </visual>
        <self_collide>0</self_collide>
        <enable_wind>0</enable_wind>
        <kinematic>0</kinematic>
      </link>
      <joint name='head_1_joint' type='revolute'>
        <pose relative_to='torso_lift_link'>0.182 0 0 0 -0 0</pose>
        <parent>torso_lift_link</parent>
        <child>head_1_link</child>
        <axis>
          <xyz>0 0 1</xyz>
          <limit>
            <lower>-1.309</lower>
            <upper>1.309</upper>
            <effort>5.197</effort>
            <velocity>3</velocity>
          </limit>
          <dynamics>
            <damping>0.5</damping>
            <friction>1</friction>
            <spring_reference>0</spring_reference>
            <spring_stiffness>0</spring_stiffness>
          </dynamics>
        </axis>
        <physics>
          <ode>
            <implicit_spring_damper>1</implicit_spring_damper>
            <cfm_damping>1</cfm_damping>
            <limit>
              <cfm>0</cfm>
              <erp>0.2</erp>
            </limit>
          </ode>
        </physics>
      </joint>
      <link name='head_1_link'>
        <pose relative_to='head_1_joint'>0 0 0 0 -0 0</pose>
        <inertial>
          <pose>-0.00508 0.00237 0.07229 0 -0 0</pose>
          <mass>0.6222</mass>
          <inertia>
            <ixx>0.001192</ixx>
            <ixy>-7e-06</ixy>
            <ixz>9.6e-05</ixz>
            <iyy>0.001402</iyy>
            <iyz>4e-06</iyz>
            <izz>0.000889</izz>
          </inertia>
        </inertial>
        <collision name='head_1_link_collision'>
          <pose>0 0 0 0 -0 0</pose>
          <geometry>
            <mesh>
              <scale>1 1 1</scale>
              <uri>/home/adriano/Desktop/tiago_public_ws/src/tiago_robot/tiago_description/meshes/head/head_1_collision.dae</uri>
            </mesh>
          </geometry>
          <surface>
            <contact>
              <ode/>
            </contact>
            <friction>
              <ode>
                <mu>0.9</mu>
                <mu2>0.9</mu2>
              </ode>
              <torsional>
                <ode/>
              </torsional>
            </friction>
            <bounce/>
          </surface>
          <max_contacts>10</max_contacts>
        </collision>
        <visual name='head_1_link_visual'>
          <pose>0 0 0 0 -0 0</pose>
          <geometry>
            <mesh>
              <scale>1 1 1</scale>
              <uri>/home/adriano/Desktop/tiago_public_ws/src/tiago_robot/tiago_description/meshes/head/head_1.stl</uri>
            </mesh>
          </geometry>
        </visual>
        <self_collide>0</self_collide>
        <enable_wind>0</enable_wind>
        <kinematic>0</kinematic>
      </link>
      <joint name='head_2_joint' type='revolute'>
        <pose relative_to='head_1_link'>0.005 0 0.098 1.5708 -0 0</pose>
        <parent>head_1_link</parent>
        <child>head_2_link</child>
        <axis>
          <xyz>0 0 1</xyz>
          <limit>
            <lower>-1.0472</lower>
            <upper>0.785398</upper>
            <effort>2.77</effort>
            <velocity>3</velocity>
          </limit>
          <dynamics>
            <damping>0.5</damping>
            <friction>1</friction>
            <spring_reference>0</spring_reference>
            <spring_stiffness>0</spring_stiffness>
          </dynamics>
        </axis>
      </joint>
      <link name='head_2_link'>
        <pose relative_to='head_2_joint'>0 0 0 0 -0 0</pose>
        <inertial>
          <pose>0.055827 0.060999 1.6e-05 0 -0 0</pose>
          <mass>0.88693</mass>
          <inertia>
            <ixx>0.00477062</ixx>
            <ixy>0.000560916</ixy>
            <ixz>1.19415e-05</ixz>
            <iyy>0.00513368</iyy>
            <iyz>9.32647e-06</iyz>
            <izz>0.00347598</izz>
          </inertia>
        </inertial>
        <collision name='head_2_link_collision'>
          <pose>0 0 0 0 -0 0</pose>
          <geometry>
            <mesh>
              <scale>1 1 1</scale>
              <uri>/home/adriano/Desktop/tiago_public_ws/src/tiago_robot/tiago_description/meshes/head/head_2_collision.dae</uri>
            </mesh>
          </geometry>
          <max_contacts>10</max_contacts>
          <surface>
            <contact>
              <ode/>
            </contact>
            <bounce/>
            <friction>
              <torsional>
                <ode/>
              </torsional>
              <ode/>
            </friction>
          </surface>
        </collision>
        <visual name='head_2_link_visual'>
          <pose>0 0 0 0 -0 0</pose>
          <geometry>
            <mesh>
              <scale>1 1 1</scale>
              <uri>/home/adriano/Desktop/tiago_public_ws/src/tiago_robot/tiago_description/meshes/head/head_2.stl</uri>
            </mesh>
          </geometry>
        </visual>
        <sensor name='xtion_frame_sensor' type='depth'>
          <always_on>1</always_on>
          <update_rate>30</update_rate>
          <camera>
            <horizontal_fov>1.09956</horizontal_fov>
            <image>
              <format>B8G8R8</format>
              <width>640</width>
              <height>480</height>
            </image>
            <clip>
              <near>0.3</near>
              <far>8</far>
            </clip>
          </camera>
          <plugin name='xtion_frame_controller' filename='libgazebo_ros_openni_kinect.so'>
            <alwaysOn>1</alwaysOn>
            <updateRate>30.0</updateRate>
            <cameraName>xtion</cameraName>
            <imageTopicName>rgb/image_raw</imageTopicName>
            <cameraInfoTopicName>rgb/camera_info</cameraInfoTopicName>
            <depthImageTopicName>depth_registered/image_raw</depthImageTopicName>
            <depthImageCameraInfoTopicName>depth_registered/camera_info</depthImageCameraInfoTopicName>
            <pointCloudTopicName>depth_registered/points</pointCloudTopicName>
            <frameName>xtion_rgb_optical_frame</frameName>
            <pointCloudCutoff>0.5</pointCloudCutoff>
            <pointCloudCutoffMax>8.0</pointCloudCutoffMax>
            <distortionK1>0.00000001</distortionK1>
            <distortionK2>0.00000001</distortionK2>
            <distortionK3>0.00000001</distortionK3>
            <distortionT1>0.00000001</distortionT1>
            <distortionT2>0.00000001</distortionT2>
            <robotNamespace>/</robotNamespace>
          </plugin>
          <pose>0.0908 0.08 -0.022 -1.5708 0 0</pose>
        </sensor>
        <self_collide>0</self_collide>
        <enable_wind>0</enable_wind>
        <kinematic>0</kinematic>
      </link>
      <plugin name='gazebo_ros_control' filename='libgazebo_ros_control.so'>
        <ns/>
        <robotSimType>pal_hardware_gazebo/PalHardwareGazebo</robotSimType>
        <robotNamespace/>
        <controlPeriod>0.001</controlPeriod>
      </plugin>
      <plugin name='gazebo_ros_p3d' filename='libgazebo_ros_p3d.so'>
        <bodyName>base_footprint</bodyName>
        <topicName>ground_truth_odom</topicName>
        <alwaysOn>1</alwaysOn>
        <updateRate>100.0</updateRate>
        <robotNamespace>/</robotNamespace>
      </plugin>
      <plugin name='gazebo_ros_odometry' filename='libgazebo_world_odometry.so'>
        <frameName>base_footprint</frameName>
        <topicName>floating_base_pose_simulated</topicName>
        <robotNamespace>/</robotNamespace>
      </plugin>
      <static>0</static>
      <gripper name='gripper_grasp'>
        <grasp_check>
          <attach_steps>1</attach_steps>
          <detach_steps>1</detach_steps>
          <min_contact_count>3</min_contact_count>
        </grasp_check>
        <gripper_link>gripper_left_finger_link</gripper_link>
        <gripper_link>gripper_right_finger_link</gripper_link>
        <palm_link>arm_7_link</palm_link>
      </gripper>
      <pose>0 0 0 0 -0 0</pose>
    </model>
    <state world_name='default'>
      <sim_time>30326 764000000</sim_time>
      <real_time>107 671130964</real_time>
      <wall_time>1695247052 974280532</wall_time>
      <iterations>77188</iterations>
      <model name='goal'>
        <pose>5.57006 0.003661 0.014353 0 -0 0</pose>
        <scale>1 1 1</scale>
        <link name='link'>
          <pose>5.57006 0.003661 0.014353 0 -0 0</pose>
          <velocity>0 0 0 0 -0 0</velocity>
          <acceleration>0 0 0 0 -0 0</acceleration>
          <wrench>0 0 0 0 -0 0</wrench>
        </link>
      </model>
      <model name='ground_plane'>
        <pose>0 0 0 0 -0 0</pose>
        <scale>1 1 1</scale>
        <link name='link'>
          <pose>0 0 0 0 -0 0</pose>
          <velocity>0 0 0 0 -0 0</velocity>
          <acceleration>0 0 0 0 -0 0</acceleration>
          <wrench>0 0 0 0 -0 0</wrench>
        </link>
      </model>
      <model name='tiago'>
        <pose>0.052427 0.001268 -0.001558 0.001252 0.000981 -0.031668</pose>
        <scale>1 1 1</scale>
        <link name='arm_1_link'>
          <pose>0.14671 0.011177 0.885667 -0.001039 0.001416 -1.40247</pose>
          <velocity>2.1e-05 9e-06 -1e-06 -2.2e-05 5.3e-05 0.000127</velocity>
          <acceleration>-0.000583 -0.00027 0.001259 2.31424 -1.27996 0.833189</acceleration>
          <wrench>-0.000912 -0.000423 0.001968 0 -0 0</wrench>
        </link>
        <link name='arm_2_link'>
          <pose>0.186842 -0.108748 0.854473 1.566 1.3402 -1.40715</pose>
          <velocity>3.6e-05 1.4e-05 1e-06 2e-06 7.6e-05 0.000128</velocity>
          <acceleration>-0.002855 6.1e-05 0.00039 -2.00743 0.490264 -0.59859</acceleration>
          <wrench>-0.005141 0.000109 0.000702 0 -0 0</wrench>
        </link>
        <link name='arm_3_link'>
          <pose>0.191655 -0.128679 0.76734 0.045481 -0.226148 -1.60743</pose>
          <velocity>3.2e-05 1.5e-05 0 8e-06 3.4e-05 -4.9e-05</velocity>
          <acceleration>-0.017174 0.002092 -0.000102 2.04281 1.18902 -2.78704</acceleration>
          <wrench>-0.030913 0.003765 -0.000183 0 -0 0</wrench>
        </link>
        <link name='arm_4_link'>
          <pose>0.17367 -0.158552 0.545538 -1.52604 0.140433 -1.59097</pose>
          <velocity>2.4e-05 1.8e-05 1e-06 4e-06 4.8e-05 -3.6e-05</velocity>
          <acceleration>-0.000924 0.002997 -2.8e-05 -1.07216 -0.614789 2.21104</acceleration>
          <wrench>-0.001324 0.004294 -4e-05 0 -0 0</wrench>
        </link>
        <link name='arm_5_link'>
          <pose>0.20482 0.003885 0.549631 0.302406 -1.42388 -1.89647</pose>
          <velocity>3.1e-05 1.7e-05 0 -1.4e-05 -0.000882 -6.7e-05</velocity>
          <acceleration>0.005142 0.000969 6e-05 0.338093 1.56109 1.57014</acceleration>
          <wrench>0.004812 0.000907 5.6e-05 0 -0 0</wrench>
        </link>
        <link name='arm_6_link'>
          <pose>0.207816 0.152375 0.570592 0.946156 -1.496 2.16779</pose>
          <velocity>4.5e-05 1.5e-05 1e-06 -4e-06 9.8e-05 0.00311</velocity>
          <acceleration>0.035231 7.9e-05 0.001024 -2.43629 -0.527048 0.551268</acceleration>
          <wrench>0.010666 2.4e-05 0.00031 0 -0 0</wrench>
        </link>
        <link name='arm_7_link'>
          <pose>0.207816 0.152374 0.570592 0.043802 -0.060657 -1.59977</pose>
          <velocity>3.6e-05 1.6e-05 1e-06 -0.000205 0.00038 0.007738</velocity>
          <acceleration>0.026415 -0.00964 0.000866 0.092459 -0.007014 2.82829</acceleration>
          <wrench>0.026488 -0.009666 0.000868 0 -0 0</wrench>
        </link>
        <link name='base_footprint'>
          <pose>0.052427 0.001268 -0.001558 0.001252 0.000981 -0.031668</pose>
          <velocity>2.2e-05 -0 5e-06 1e-06 -0 0.000111</velocity>
          <acceleration>6.1e-05 -2.2e-05 -9e-06 -0.000335 0.000608 0.000946</acceleration>
          <wrench>0.002609 -0.000949 -0.000383 0 -0 0</wrench>
        </link>
        <link name='caster_back_left_1_link'>
          <pose>-0.117689 0.108629 0.064109 0.001342 0.012166 0.426562</pose>
          <velocity>1.7e-05 -1.6e-05 5.1e-05 -0.000597 0.00129 -0.004996</velocity>
          <acceleration>-1e-06 1e-05 4.2e-05 -0.043777 0.16106 -0.02284</acceleration>
          <wrench>-0 1e-06 2e-06 0 -0 0</wrench>
        </link>
        <link name='caster_back_left_2_link'>
          <pose>-0.132499 0.101957 0.024489 -1.56968 0.035763 0.426589</pose>
          <velocity>-3.9e-05 4.7e-05 0.000101 -0.000958 0.002101 -0.004995</velocity>
          <acceleration>-9e-06 3e-06 3e-06 -6e-05 -0.000522 0.00045</acceleration>
          <wrench>-1e-06 0 0 0 -0 0</wrench>
        </link>
        <link name='caster_back_right_1_link'>
          <pose>-0.12415 -0.095261 0.063987 0.00047 0.015375 1.15747</pose>
          <velocity>3.7e-05 -1e-05 6.7e-05 -0.001801 0.000716 -0.001906</velocity>
          <acceleration>-1.7e-05 1.7e-05 3.4e-05 -0.106754 0.137643 -0.040737</acceleration>
          <wrench>-1e-06 1e-06 2e-06 0 -0 0</wrench>
        </link>
        <link name='caster_back_right_2_link'>
          <pose>-0.130708 -0.110165 0.024485 -1.57026 0.394452 1.15767</pose>
          <velocity>-2e-06 -3e-05 0.000136 -0.002592 0.001156 -0.001915</velocity>
          <acceleration>-1.2e-05 9e-06 2e-06 -0.000371 -0.000732 0.000964</acceleration>
          <wrench>-1e-06 1e-06 0 0 -0 0</wrench>
        </link>
        <link name='caster_front_left_1_link'>
          <pose>0.225135 0.097757 0.063925 -0.000124 0.018556 -1.33859</pose>
          <velocity>1.4e-05 8e-06 6.9e-05 0.00198 0.000433 1e-06</velocity>
          <acceleration>-2.4e-05 2.1e-05 -4.7e-05 -0.005855 -0.006945 -0.003234</acceleration>
          <wrench>-1e-06 1e-06 -2e-06 0 -0 0</wrench>
        </link>
        <link name='caster_front_left_2_link'>
          <pose>0.22136 0.113713 0.024485 1.57099 0.422237 1.80308</pose>
          <velocity>8e-06 4.3e-05 0.000141 0.002601 0.000633 -6e-06</velocity>
          <acceleration>-1.9e-05 2.3e-05 -3e-06 -0.000967 -0.000903 -0.000412</acceleration>
          <wrench>-2e-06 2e-06 -0 0 -0 0</wrench>
        </link>
        <link name='caster_front_right_1_link'>
          <pose>0.218676 -0.106144 0.063792 4.4e-05 0.02268 -1.32357</pose>
          <velocity>3.7e-05 5e-06 8.4e-05 0.00245 0.000569 0.000357</velocity>
          <acceleration>-3.1e-05 2.6e-05 -5.7e-05 0.019612 0.01769 0.006085</acceleration>
          <wrench>-2e-06 1e-06 -3e-06 0 -0 0</wrench>
        </link>
        <link name='caster_front_right_2_link'>
          <pose>0.214648 -0.090165 0.024481 1.57088 0.101844 1.81802</pose>
          <velocity>2.3e-05 4.7e-05 0.000173 0.003727 0.000964 0.000355</velocity>
          <acceleration>-2.2e-05 2.7e-05 -3e-06 -0.001086 -0.001163 -0.000644</acceleration>
          <wrench>-2e-06 2e-06 -0 0 -0 0</wrench>
        </link>
        <link name='gripper_left_finger_link'>
          <pose>0.249516 0.155925 0.648918 -3.08087 0.043716 3.11531</pose>
          <velocity>0.000121 0.000353 -1e-05 -0.000344 0.000333 0.008156</velocity>
          <acceleration>0.01134 0.440797 -0.020585 -0.319396 -1.37395 -2.39608</acceleration>
          <wrench>0.001247 0.048479 -0.002264 0 -0 0</wrench>
        </link>
        <link name='gripper_right_finger_link'>
          <pose>0.159658 0.158292 0.644985 -3.08087 0.043741 3.1152</pose>
          <velocity>3.6e-05 -0.000347 1.7e-05 -7.8e-05 0.000383 0.008339</velocity>
          <acceleration>-0.098888 -0.415111 0.019218 0.461899 -0.033565 0.50777</acceleration>
          <wrench>-0.010876 -0.045654 0.002114 0 -0 0</wrench>
        </link>
        <link name='head_1_link'>
          <pose>0.173347 -0.003863 1.03663 0.001323 0.000887 0.043437</pose>
          <velocity>2.3e-05 1.2e-05 -1e-06 1e-06 -0 0.000113</velocity>
          <acceleration>0.000401 -0.000132 -0.000455 -1.58011 -0.602294 -0.229437</acceleration>
          <wrench>0.000249 -8.2e-05 -0.000283 0 -0 0</wrench>
        </link>
        <link name='head_2_link'>
          <pose>0.178436 -0.003772 1.13463 1.57212 0.030818 0.043478</pose>
          <velocity>2.3e-05 1.2e-05 -1e-06 2e-06 -4e-06 0.000113</velocity>
          <acceleration>0.0003 -7.9e-05 -0.000305 -0.830382 -0.89742 -0.766128</acceleration>
          <wrench>0.000266 -7e-05 -0.000271 0 -0 0</wrench>
        </link>
        <link name='suspension_left_link'>
          <pose>0.052519 0.001143 0.096189 0.001252 0.000982 -0.031668</pose>
          <velocity>2.2e-05 -0 8.2e-05 1e-06 -0 0.000111</velocity>
          <acceleration>-2.4e-05 -4e-06 -1.2e-05 0.000135 0.000625 -4.2e-05</acceleration>
          <wrench>-0.000236 -4.2e-05 -0.000121 0 -0 0</wrench>
        </link>
        <link name='suspension_right_link'>
          <pose>0.052519 0.001142 0.096696 0.001252 0.000982 -0.031668</pose>
          <velocity>2.3e-05 -0 8.3e-05 1e-06 -0 0.000111</velocity>
          <acceleration>-2.5e-05 -4e-06 1.2e-05 0.000135 0.000632 -3.8e-05</acceleration>
          <wrench>-0.000249 -4.3e-05 0.000118 0 -0 0</wrench>
        </link>
        <link name='torso_lift_link'>
          <pose>-0.008564 0.0019 1.03681 0.001252 0.000984 -0.031668</pose>
          <velocity>2.2e-05 -8e-06 -1e-06 1e-06 -0 0.000111</velocity>
          <acceleration>0.00045 -0.000103 -0.000388 -0.002342 0.000586 -0.017234</acceleration>
          <wrench>0.00312 -0.000716 -0.002688 0 -0 0</wrench>
        </link>
        <link name='wheel_left_link'>
          <pose>0.058921 0.203241 0.096442 -1.56405 1.38564 -0.025041</pose>
          <velocity>0 0 8.3e-05 1e-06 2e-06 0.000111</velocity>
          <acceleration>-1e-06 -8e-06 1.2e-05 -2.5e-05 -0.003421 -6.4e-05</acceleration>
          <wrench>-1e-06 -1.5e-05 2.1e-05 0 -0 0</wrench>
        </link>
        <link name='wheel_right_link'>
          <pose>0.046117 -0.200956 0.096442 -1.56872 -0.930849 -0.033337</pose>
          <velocity>4.5e-05 -1e-06 8.3e-05 1.5e-05 0.000457 0.000111</velocity>
          <acceleration>-1.9e-05 -8e-06 -1.2e-05 -0.020891 -0.662632 0.000501</acceleration>
          <wrench>-3.4e-05 -1.4e-05 -2.2e-05 0 -0 0</wrench>
        </link>
      </model>
      <model name='wall_long'>
        <pose>1.93735 0.724323 0 0 -0 0</pose>
        <scale>1 1 1</scale>
        <link name='link'>
          <pose>2.42755 -1.43187 0.794503 0 0 -1.57541</pose>
          <velocity>0 0 0 0 -0 0</velocity>
          <acceleration>0 0 0 0 -0 0</acceleration>
          <wrench>0 0 0 0 -0 0</wrench>
        </link>
      </model>
      <light name='sun'>
        <pose>0 0 10 0 -0 0</pose>
      </light>
    </state>
    <gui fullscreen='0'>
      <camera name='user_camera'>
        <pose>0.168539 8.22148 9.07737 -0 0.7058 -1.34906</pose>
        <view_controller>orbit</view_controller>
        <projection_type>perspective</projection_type>
      </camera>
    </gui>
    <model name='goal'>
      <link name='link'>
        <inertial>
          <mass>2.33165</mass>
          <inertia>
            <ixx>0.0190484</ixx>
            <ixy>0</ixy>
            <ixz>0</ixz>
            <iyy>0.0190484</iyy>
            <iyz>0</iyz>
            <izz>0.0377765</izz>
          </inertia>
          <pose>0 0 0 0 -0 0</pose>
        </inertial>
        <self_collide>0</self_collide>
        <enable_wind>0</enable_wind>
        <kinematic>0</kinematic>
        <pose>0 0 0 0 -0 0</pose>
        <gravity>1</gravity>
        <visual name='visual'>
          <geometry>
            <cylinder>
              <radius>0.180009</radius>
              <length>0.0287069</length>
            </cylinder>
          </geometry>
          <material>
            <script>
              <name>Gazebo/Blue</name>
              <uri>file://media/materials/scripts/gazebo.material</uri>
            </script>
            <shader type='pixel'>
              <normal_map>__default__</normal_map>
            </shader>
            <ambient>0.3 0.3 0.3 1</ambient>
            <diffuse>0.7 0.7 0.7 1</diffuse>
            <specular>0.01 0.01 0.01 1</specular>
            <emissive>1 0 0 1</emissive>
          </material>
          <pose>0 0 0 0 -0 0</pose>
          <transparency>0</transparency>
          <cast_shadows>1</cast_shadows>
        </visual>
        <collision name='collision'>
          <laser_retro>0</laser_retro>
          <max_contacts>10</max_contacts>
          <pose>0 0 0 0 -0 0</pose>
          <geometry>
            <cylinder>
              <radius>0.180009</radius>
              <length>0.028707</length>
            </cylinder>
          </geometry>
          <surface>
            <friction>
              <ode>
                <mu>1</mu>
                <mu2>1</mu2>
                <fdir1>0 0 0</fdir1>
                <slip1>0</slip1>
                <slip2>0</slip2>
              </ode>
              <torsional>
                <coefficient>1</coefficient>
                <patch_radius>0</patch_radius>
                <surface_radius>0</surface_radius>
                <use_patch_radius>1</use_patch_radius>
                <ode>
                  <slip>0</slip>
                </ode>
              </torsional>
            </friction>
            <bounce>
              <restitution_coefficient>0</restitution_coefficient>
              <threshold>1e+06</threshold>
            </bounce>
            <contact>
              <collide_without_contact>0</collide_without_contact>
              <collide_without_contact_bitmask>1</collide_without_contact_bitmask>
              <collide_bitmask>1</collide_bitmask>
              <ode>
                <soft_cfm>0</soft_cfm>
                <soft_erp>0.2</soft_erp>
                <kp>1e+13</kp>
                <kd>1</kd>
                <max_vel>0.01</max_vel>
                <min_depth>0</min_depth>
              </ode>
              <bullet>
                <split_impulse>1</split_impulse>
                <split_impulse_penetration_threshold>-0.01</split_impulse_penetration_threshold>
                <soft_cfm>0</soft_cfm>
                <soft_erp>0.2</soft_erp>
                <kp>1e+13</kp>
                <kd>1</kd>
              </bullet>
            </contact>
          </surface>
        </collision>
      </link>
      <static>0</static>
      <allow_auto_disable>1</allow_auto_disable>
      <pose>5.57006 0.003661 0 0 -0 0</pose>
    </model>
    <model name='wall_long'>
      <link name='link'>
        <pose>0.490196 -2.15619 0.794503 0 0 -1.57541</pose>
        <self_collide>0</self_collide>
        <enable_wind>0</enable_wind>
        <kinematic>0</kinematic>
        <inertial>
          <inertia>
            <ixx>0</ixx>
            <ixy>0</ixy>
            <ixz>0</ixz>
            <iyy>0</iyy>
            <iyz>0</iyz>
            <izz>0</izz>
          </inertia>
          <mass>0</mass>
          <pose>0 0 0 0 -0 0</pose>
        </inertial>
        <visual name='visual'>
          <cast_shadows>0</cast_shadows>
          <geometry>
            <box>
              <size>17.3893 0.2 1.6945</size>
            </box>
          </geometry>
          <material>
            <script>
              <uri>model://grey_wall/materials/scripts</uri>
              <uri>model://grey_wall/materials/textures</uri>
              <name>vrc/grey_wall</name>
            </script>
            <shader type='pixel'/>
          </material>
          <pose>0 0 0 0 -0 0</pose>
          <transparency>0</transparency>
        </visual>
        <collision name='collision'>
          <laser_retro>0</laser_retro>
          <max_contacts>10</max_contacts>
          <pose>0 0 0 0 -0 0</pose>
          <geometry>
            <box>
              <size>17.3893 0.2 1.6945</size>
            </box>
          </geometry>
          <surface>
            <friction>
              <ode>
                <mu>1</mu>
                <mu2>1</mu2>
                <fdir1>0 0 0</fdir1>
                <slip1>0</slip1>
                <slip2>0</slip2>
              </ode>
              <torsional>
                <coefficient>1</coefficient>
                <patch_radius>0</patch_radius>
                <surface_radius>0</surface_radius>
                <use_patch_radius>1</use_patch_radius>
                <ode>
                  <slip>0</slip>
                </ode>
              </torsional>
            </friction>
            <bounce>
              <restitution_coefficient>0</restitution_coefficient>
              <threshold>1e+06</threshold>
            </bounce>
            <contact>
              <collide_without_contact>0</collide_without_contact>
              <collide_without_contact_bitmask>1</collide_without_contact_bitmask>
              <collide_bitmask>1</collide_bitmask>
              <ode>
                <soft_cfm>0</soft_cfm>
                <soft_erp>0.2</soft_erp>
                <kp>1e+13</kp>
                <kd>1</kd>
                <max_vel>0.01</max_vel>
                <min_depth>0</min_depth>
              </ode>
              <bullet>
                <split_impulse>1</split_impulse>
                <split_impulse_penetration_threshold>-0.01</split_impulse_penetration_threshold>
                <soft_cfm>0</soft_cfm>
                <soft_erp>0.2</soft_erp>
                <kp>1e+13</kp>
                <kd>1</kd>
              </bullet>
            </contact>
          </surface>
        </collision>
      </link>
      <static>1</static>
      <allow_auto_disable>1</allow_auto_disable>
      <pose>1.93735 0.724323 0 0 -0 0</pose>
    </model>
  </world>
</sdf>
